Workbook

Sheet BETA
C3: Date | D3: =TODAY() -> 43432
D6: Beta 30 Days | E6: Beta 30 Days | F6: Beta 1 Year
C7: ='STOCK (1)'!$A$2 -> IBULHSGFIN | D7: =SLOPE(BETA_CAL!D$5:D$33,BETA_CAL!$B$5:$B$33) -> #N/A | E7: =SLOPE(BETA_CAL!D$5:D$93,BETA_CAL!$B$5:$B$93) -> #N/A | F7: =SLOPE(BETA_CAL!D$5:D$251,BETA_CAL!$B$5:$B$251) -> #N/A
C8: ='STOCK (2)'!$A$2 -> INDIGO | D8: =SLOPE(BETA_CAL!E$5:E$33,BETA_CAL!$B$5:$B$33) -> #N/A | E8: =SLOPE(BETA_CAL!E$5:E$93,BETA_CAL!$B$5:$B$93) -> #N/A | F8: =SLOPE(BETA_CAL!E$5:E$251,BETA_CAL!$B$5:$B$251) -> #N/A
C9: ='STOCK (3)'!$A$2 -> ONGC | D9: =SLOPE(BETA_CAL!F$5:F$33,BETA_CAL!$B$5:$B$33) -> #N/A | E9: =SLOPE(BETA_CAL!F$5:F$93,BETA_CAL!$B$5:$B$93) -> #N/A | F9: =SLOPE(BETA_CAL!F$5:F$251,BETA_CAL!$B$5:$B$251) -> #N/A
C10: ='STOCK (4)'!$A$2 -> GODREJCP | D10: =SLOPE(BETA_CAL!G$5:G$33,BETA_CAL!$B$5:$B$33) -> #N/A | E10: =SLOPE(BETA_CAL!G$5:G$93,BETA_CAL!$B$5:$B$93) -> #N/A | F10: =SLOPE(BETA_CAL!G$5:G$251,BETA_CAL!$B$5:$B$251) -> #N/A
C11: ='STOCK (5)'!$A$2 -> SBIN | D11: =SLOPE(BETA_CAL!H$5:H$33,BETA_CAL!$B$5:$B$33) -> #N/A | E11: =SLOPE(BETA_CAL!H$5:H$93,BETA_CAL!$B$5:$B$93) -> #N/A | F11: =SLOPE(BETA_CAL!H$5:H$251,BETA_CAL!$B$5:$B$251) -> #N/A
C12: ='STOCK (5)'!$A$2 -> SBIN | D12: =SLOPE(BETA_CAL!I$5:I$33,BETA_CAL!$B$5:$B$33) -> #DIV/0! | E12: =SLOPE(BETA_CAL!I$5:I$93,BETA_CAL!$B$5:$B$93) -> #DIV/0! | F12: =SLOPE(BETA_CAL!I$5:I$251,BETA_CAL!$B$5:$B$251) -> #DIV/0!
C13: ='STOCK (5)'!$A$2 -> SBIN | D13: =SLOPE(BETA_CAL!J$5:J$33,BETA_CAL!$B$5:$B$33) -> #DIV/0! | E13: =SLOPE(BETA_CAL!J$5:J$93,BETA_CAL!$B$5:$B$93) -> #DIV/0! | F13: =SLOPE(BETA_CAL!J$5:J$251,BETA_CAL!$B$5:$B$251) -> #DIV/0!
C14: ='STOCK (5)'!$A$2 -> SBIN | D14: =SLOPE(BETA_CAL!K$5:K$33,BETA_CAL!$B$5:$B$33) -> #DIV/0! | E14: =SLOPE(BETA_CAL!K$5:K$93,BETA_CAL!$B$5:$B$93) -> #DIV/0! | F14: =SLOPE(BETA_CAL!K$5:K$251,BETA_CAL!$B$5:$B$251) -> #DIV/0!
C15: ='STOCK (5)'!$A$2 -> SBIN | D15: =SLOPE(BETA_CAL!L$5:L$33,BETA_CAL!$B$5:$B$33) -> #DIV/0! | E15: =SLOPE(BETA_CAL!L$5:L$93,BETA_CAL!$B$5:$B$93) -> #DIV/0! | F15: =SLOPE(BETA_CAL!L$5:L$251,BETA_CAL!$B$5:$B$251) -> #DIV/0!
C16: ='STOCK (5)'!$A$2 -> SBIN | D16: =SLOPE(BETA_CAL!M$5:M$33,BETA_CAL!$B$5:$B$33) -> #DIV/0! | E16: =SLOPE(BETA_CAL!M$5:M$93,BETA_CAL!$B$5:$B$93) -> #DIV/0! | F16: =SLOPE(BETA_CAL!M$5:M$251,BETA_CAL!$B$5:$B$251) -> #DIV/0!
C17: ='STOCK (5)'!$A$2 -> SBIN | D17: =SLOPE(BETA_CAL!N$5:N$33,BETA_CAL!$B$5:$B$33) -> #DIV/0! | E17: =SLOPE(BETA_CAL!N$5:N$93,BETA_CAL!$B$5:$B$93) -> #DIV/0! | F17: =SLOPE(BETA_CAL!N$5:N$251,BETA_CAL!$B$5:$B$251) -> #DIV/0!
C18: ='STOCK (5)'!$A$2 -> SBIN | D18: =SLOPE(BETA_CAL!O$5:O$33,BETA_CAL!$B$5:$B$33) -> #DIV/0! | E18: =SLOPE(BETA_CAL!O$5:O$93,BETA_CAL!$B$5:$B$93) -> #DIV/0! | F18: =SLOPE(BETA_CAL!O$5:O$251,BETA_CAL!$B$5:$B$251) -> #DIV/0!
C19: ='STOCK (5)'!$A$2 -> SBIN | D19: =SLOPE(BETA_CAL!P$5:P$33,BETA_CAL!$B$5:$B$33) -> #DIV/0! | E19: =SLOPE(BETA_CAL!P$5:P$93,BETA_CAL!$B$5:$B$93) -> #DIV/0! | F19: =SLOPE(BETA_CAL!P$5:P$251,BETA_CAL!$B$5:$B$251) -> #DIV/0!
C20: ='STOCK (5)'!$A$2 -> SBIN | D20: =SLOPE(BETA_CAL!Q$5:Q$33,BETA_CAL!$B$5:$B$33) -> #DIV/0! | E20: =SLOPE(BETA_CAL!Q$5:Q$93,BETA_CAL!$B$5:$B$93) -> #DIV/0! | F20: =SLOPE(BETA_CAL!Q$5:Q$251,BETA_CAL!$B$5:$B$251) -> #DIV/0!
C21: ='STOCK (5)'!$A$2 -> SBIN | D21: =SLOPE(BETA_CAL!R$5:R$33,BETA_CAL!$B$5:$B$33) -> #DIV/0! | E21: =SLOPE(BETA_CAL!R$5:R$93,BETA_CAL!$B$5:$B$93) -> #DIV/0! | F21: =SLOPE(BETA_CAL!R$5:R$251,BETA_CAL!$B$5:$B$251) -> #DIV/0!
C22: ='STOCK (5)'!$A$2 -> SBIN | D22: =SLOPE(BETA_CAL!S$5:S$33,BETA_CAL!$B$5:$B$33) -> #DIV/0! | E22: =SLOPE(BETA_CAL!S$5:S$93,BETA_CAL!$B$5:$B$93) -> #DIV/0! | F22: =SLOPE(BETA_CAL!S$5:S$251,BETA_CAL!$B$5:$B$251) -> #DIV/0!
C23: ='STOCK (5)'!$A$2 -> SBIN | D23: =SLOPE(BETA_CAL!T$5:T$33,BETA_CAL!$B$5:$B$33) -> #DIV/0! | E23: =SLOPE(BETA_CAL!T$5:T$93,BETA_CAL!$B$5:$B$93) -> #DIV/0! | F23: =SLOPE(BETA_CAL!T$5:T$251,BETA_CAL!$B$5:$B$251) -> #DIV/0!
C24: ='STOCK (5)'!$A$2 -> SBIN | D24: =SLOPE(BETA_CAL!U$5:U$33,BETA_CAL!$B$5:$B$33) -> #DIV/0! | E24: =SLOPE(BETA_CAL!U$5:U$93,BETA_CAL!$B$5:$B$93) -> #DIV/0! | F24: =SLOPE(BETA_CAL!U$5:U$251,BETA_CAL!$B$5:$B$251) -> #DIV/0!
C25: ='STOCK (5)'!$A$2 -> SBIN | D25: =SLOPE(BETA_CAL!V$5:V$33,BETA_CAL!$B$5:$B$33) -> #DIV/0! | E25: =SLOPE(BETA_CAL!V$5:V$93,BETA_CAL!$B$5:$B$93) -> #DIV/0! | F25: =SLOPE(BETA_CAL!V$5:V$251,BETA_CAL!$B$5:$B$251) -> #DIV/0!
C26: ='STOCK (5)'!$A$2 -> SBIN | D26: =SLOPE(BETA_CAL!W$5:W$33,BETA_CAL!$B$5:$B$33) -> #DIV/0! | E26: =SLOPE(BETA_CAL!W$5:W$93,BETA_CAL!$B$5:$B$93) -> #DIV/0! | F26: =SLOPE(BETA_CAL!W$5:W$251,BETA_CAL!$B$5:$B$251) -> #DIV/0!
C27: ='STOCK (5)'!$A$2 -> SBIN | D27: =SLOPE(BETA_CAL!X$5:X$33,BETA_CAL!$B$5:$B$33) -> #DIV/0! | E27: =SLOPE(BETA_CAL!X$5:X$93,BETA_CAL!$B$5:$B$93) -> #DIV/0! | F27: =SLOPE(BETA_CAL!X$5:X$251,BETA_CAL!$B$5:$B$251) -> #DIV/0!
C28: ='STOCK (5)'!$A$2 -> SBIN | D28: =SLOPE(BETA_CAL!Y$5:Y$33,BETA_CAL!$B$5:$B$33) -> #DIV/0! | E28: =SLOPE(BETA_CAL!Y$5:Y$93,BETA_CAL!$B$5:$B$93) -> #DIV/0! | F28: =SLOPE(BETA_CAL!Y$5:Y$251,BETA_CAL!$B$5:$B$251) -> #DIV/0!
C29: ='STOCK (5)'!$A$2 -> SBIN | D29: =SLOPE(BETA_CAL!Z$5:Z$33,BETA_CAL!$B$5:$B$33) -> #DIV/0! | E29: =SLOPE(BETA_CAL!Z$5:Z$93,BETA_CAL!$B$5:$B$93) -> #DIV/0! | F29: =SLOPE(BETA_CAL!Z$5:Z$251,BETA_CAL!$B$5:$B$251) -> #DIV/0!
C30: ='STOCK (5)'!$A$2 -> SBIN | D30: =SLOPE(BETA_CAL!AA$5:AA$33,BETA_CAL!$B$5:$B$33) -> #DIV/0! | E30: =SLOPE(BETA_CAL!AA$5:AA$93,BETA_CAL!$B$5:$B$93) -> #DIV/0! | F30: =SLOPE(BETA_CAL!AA$5:AA$251,BETA_CAL!$B$5:$B$251) -> #DIV/0!
C31: ='STOCK (5)'!$A$2 -> SBIN | D31: =SLOPE(BETA_CAL!AB$5:AB$33,BETA_CAL!$B$5:$B$33) -> #DIV/0! | E31: =SLOPE(BETA_CAL!AB$5:AB$93,BETA_CAL!$B$5:$B$93) -> #DIV/0! | F31: =SLOPE(BETA_CAL!AB$5:AB$251,BETA_CAL!$B$5:$B$251) -> #DIV/0!
C32: ='STOCK (5)'!$A$2 -> SBIN | D32: =SLOPE(BETA_CAL!AC$5:AC$33,BETA_CAL!$B$5:$B$33) -> #DIV/0! | E32: =SLOPE(BETA_CAL!AC$5:AC$93,BETA_CAL!$B$5:$B$93) -> #DIV/0! | F32: =SLOPE(BETA_CAL!AC$5:AC$251,BETA_CAL!$B$5:$B$251) -> #DIV/0!
C33: ='STOCK (5)'!$A$2 -> SBIN | D33: =SLOPE(BETA_CAL!AD$5:AD$33,BETA_CAL!$B$5:$B$33) -> #DIV/0! | E33: =SLOPE(BETA_CAL!AD$5:AD$93,BETA_CAL!$B$5:$B$93) -> #DIV/0! | F33: =SLOPE(BETA_CAL!AD$5:AD$251,BETA_CAL!$B$5:$B$251) -> #DIV/0!
C34: ='STOCK (5)'!$A$2 -> SBIN | D34: =SLOPE(BETA_CAL!AE$5:AE$33,BETA_CAL!$B$5:$B$33) -> #DIV/0! | E34: =SLOPE(BETA_CAL!AE$5:AE$93,BETA_CAL!$B$5:$B$93) -> #DIV/0! | F34: =SLOPE(BETA_CAL!AE$5:AE$251,BETA_CAL!$B$5:$B$251) -> #DIV/0!
C35: ='STOCK (5)'!$A$2 -> SBIN | D35: =SLOPE(BETA_CAL!AF$5:AF$33,BETA_CAL!$B$5:$B$33) -> #DIV/0! | E35: =SLOPE(BETA_CAL!AF$5:AF$93,BETA_CAL!$B$5:$B$93) -> #DIV/0! | F35: =SLOPE(BETA_CAL!AF$5:AF$251,BETA_CAL!$B$5:$B$251) -> #DIV/0!
C36: ='STOCK (5)'!$A$2 -> SBIN | D36: =SLOPE(BETA_CAL!AG$5:AG$33,BETA_CAL!$B$5:$B$33) -> #DIV/0! | E36: =SLOPE(BETA_CAL!AG$5:AG$93,BETA_CAL!$B$5:$B$93) -> #DIV/0! | F36: =SLOPE(BETA_CAL!AG$5:AG$251,BETA_CAL!$B$5:$B$251) -> #DIV/0!
C37: ='STOCK (5)'!$A$2 -> SBIN | D37: =SLOPE(BETA_CAL!AH$5:AH$33,BETA_CAL!$B$5:$B$33) -> #DIV/0! | E37: =SLOPE(BETA_CAL!AH$5:AH$93,BETA_CAL!$B$5:$B$93) -> #DIV/0! | F37: =SLOPE(BETA_CAL!AH$5:AH$251,BETA_CAL!$B$5:$B$251) -> #DIV/0!
C38: ='STOCK (5)'!$A$2 -> SBIN | D38: =SLOPE(BETA_CAL!AI$5:AI$33,BETA_CAL!$B$5:$B$33) -> #DIV/0! | E38: =SLOPE(BETA_CAL!AI$5:AI$93,BETA_CAL!$B$5:$B$93) -> #DIV/0! | F38: =SLOPE(BETA_CAL!AI$5:AI$251,BETA_CAL!$B$5:$B$251) -> #DIV/0!
C39: ='STOCK (5)'!$A$2 -> SBIN | D39: =SLOPE(BETA_CAL!AJ$5:AJ$33,BETA_CAL!$B$5:$B$33) -> #DIV/0! | E39: =SLOPE(BETA_CAL!AJ$5:AJ$93,BETA_CAL!$B$5:$B$93) -> #DIV/0! | F39: =SLOPE(BETA_CAL!AJ$5:AJ$251,BETA_CAL!$B$5:$B$251) -> #DIV/0!
C40: ='STOCK (5)'!$A$2 -> SBIN | D40: =SLOPE(BETA_CAL!AK$5:AK$33,BETA_CAL!$B$5:$B$33) -> #DIV/0! | E40: =SLOPE(BETA_CAL!AK$5:AK$93,BETA_CAL!$B$5:$B$93) -> #DIV/0! | F40: =SLOPE(BETA_CAL!AK$5:AK$251,BETA_CAL!$B$5:$B$251) -> #DIV/0!
C41: ='STOCK (5)'!$A$2 -> SBIN | D41: =SLOPE(BETA_CAL!AL$5:AL$33,BETA_CAL!$B$5:$B$33) -> #DIV/0! | E41: =SLOPE(BETA_CAL!AL$5:AL$93,BETA_CAL!$B$5:$B$93) -> #DIV/0! | F41: =SLOPE(BETA_CAL!AL$5:AL$251,BETA_CAL!$B$5:$B$251) -> #DIV/0!
C42: ='STOCK (5)'!$A$2 -> SBIN | D42: =SLOPE(BETA_CAL!AM$5:AM$33,BETA_CAL!$B$5:$B$33) -> #DIV/0! | E42: =SLOPE(BETA_CAL!AM$5:AM$93,BETA_CAL!$B$5:$B$93) -> #DIV/0! | F42: =SLOPE(BETA_CAL!AM$5:AM$251,BETA_CAL!$B$5:$B$251) -> #DIV/0!
C43: ='STOCK (5)'!$A$2 -> SBIN | D43: =SLOPE(BETA_CAL!AN$5:AN$33,BETA_CAL!$B$5:$B$33) -> #DIV/0! | E43: =SLOPE(BETA_CAL!AN$5:AN$93,BETA_CAL!$B$5:$B$93) -> #DIV/0! | F43: =SLOPE(BETA_CAL!AN$5:AN$251,BETA_CAL!$B$5:$B$251) -> #DIV/0!
C44: ='STOCK (5)'!$A$2 -> SBIN | D44: =SLOPE(BETA_CAL!AO$5:AO$33,BETA_CAL!$B$5:$B$33) -> #DIV/0! | E44: =SLOPE(BETA_CAL!AO$5:AO$93,BETA_CAL!$B$5:$B$93) -> #DIV/0! | F44: =SLOPE(BETA_CAL!AO$5:AO$251,BETA_CAL!$B$5:$B$251) -> #DIV/0!
...

Sheet BETA_CAL
D3: Stock1 | E3: Stock2 | F3: Stock3 | G3: Stock4 | H3: Stock5 | I3: Stock6 | J3: Stock7 | K3: Stock8 | L3: Stock9 | M3: Stock10 | N3: Stock11 | O3: Stock12 | P3: Stock13 | Q3: Stock14 | R3: Stock15 | S3: Stock16 | T3: Stock17 | U3: Stock18 | V3: Stock19 | W3: Stock20 | X3: Stock21 | Y3: Stock22 | Z3: Stock23 | AA3: Stock24 | AB3: Stock25 | AC3: Stock26 | AD3: Stock27 | AE3: Stock28 | AF3: Stock29 | AG3: Stock30 | AH3: Stock31 | AI3: Stock32 | AJ3: Stock33 | AK3: Stock34 | AL3: Stock35 | AM3: Stock36 | AN3: Stock37 | AO3: Stock38 | AP3: Stock39 | AQ3: Stock40 | AR3: Stock41 | AS3: Stock42 | AT3: Stock43 | AU3: Stock44 | AV3: Stock45 | AW3: Stock46 | AX3: Stock47 | AY3: Stock48 | AZ3: Stock49 | BA3: Stock50 | BB3: Stock51 | BC3: Stock52 | BD3: Stock53 | BE3: Stock54 | BF3: Stock55 | BG3: Stock56 | BH3: Stock57 | BI3: Stock58 | BJ3: Stock59 | BK3: Stock60 | BL3: Stock61 | BM3: Stock62 | BN3: Stock63 | BO3: Stock64 | BP3: Stock65 | BQ3: Stock66 | BR3: Stock67 | BS3: Stock68 | BT3: Stock69 | BU3: Stock70 | BV3: Stock71 | BW3: Stock72 | BX3: Stock73 | BY3: Stock74 | BZ3: Stock75 | CA3: Stock76 | CB3: Stock77 | CC3: Stock78 | CD3: Stock79 | CE3: Stock80 | CF3: Stock81 | CG3: Stock82 | CH3: Stock83 | CI3: Stock84 | CJ3: Stock85 | CK3: Stock86 | CL3: Stock87 | CM3: Stock88 | CN3: Stock89 | CO3: Stock90 | CP3: Stock91 | CQ3: Stock92 | CR3: Stock93 | CS3: Stock94 | CT3: Stock95 | CU3: Stock96 | CV3: Stock97 | CW3: Stock98 | CX3: Stock99 | CY3: Stock100 | CZ3: Stock101 | DA3: Stock102 | DB3: Stock103 | DC3: Stock104 | DD3: Stock105 | DE3: Stock106 | DF3: Stock107 | DG3: Stock108 | DH3: Stock109 | DI3: Stock110 | DJ3: Stock111 | DK3: Stock112 | DL3: Stock113 | DM3: Stock114 | DN3: Stock115 | DO3: Stock116 | DP3: Stock117 | DQ3: Stock118 | DR3: Stock119 | DS3: Stock120 | DT3: Stock121 | DU3: Stock122 | DV3: Stock123 | DW3: Stock124 | DX3: Stock125 | DY3: Stock126 | DZ3: Stock127 | EA3: Stock128 | EB3: Stock129 | EC3: Stock130 | ED3: Stock131 | EE3: Stock132 | EF3: Stock133 | EG3: Stock134 | EH3: Stock135 | EI3: Stock136 | EJ3: Stock137 | EK3: Stock138 | EL3: Stock139 | EM3: Stock140 | EN3: Stock141 | EO3: Stock142 | EP3: Stock143 | EQ3: Stock144 | ER3: Stock145 | ES3: Stock146 | ET3: Stock147 | EU3: Stock148 | EV3: Stock149 | EW3: Stock150 | EX3: Stock151 | EY3: Stock152 | EZ3: Stock153 | FA3: Stock154 | FB3: Stock155 | FC3: Stock156 | FD3: Stock157 | FE3: Stock158 | FF3: Stock159 | FG3: Stock160 | FH3: Stock161 | FI3: Stock162 | FJ3: Stock163 | FK3: Stock164 | FL3: Stock165 | FM3: Stock166 | FN3: Stock167 | FO3: Stock168 | FP3: Stock169 | FQ3: Stock170 | FR3: Stock171 | FS3: Stock172 | FT3: Stock173 | FU3: Stock174 | FV3: Stock175 | FW3: Stock176 | FX3: Stock177 | FY3: Stock178 | FZ3: Stock179 | GA3: Stock180 | GB3: Stock181 | GC3: Stock182 | GD3: Stock183 | GE3: Stock184 | GF3: Stock185 | GG3: Stock186 | GH3: Stock187 | GI3: Stock188 | GJ3: Stock189 | GK3: Stock190 | GL3: Stock191 | GM3: Stock192 | GN3: Stock193 | GO3: Stock194 | GP3: Stock195 | GQ3: Stock196 | GR3: Stock197 | GS3: Stock198 | GT3: Stock199 | GU3: Stock200 | GV3: Stock201 | GW3: Stock202 | GX3: Stock203 | GY3: Stock204 | GZ3: Stock205 | HA3: Stock206 | HB3: Stock207 | HC3: Stock208 | HD3: Stock209 | HE3: Stock210 | HF3: Stock211 | HG3: Stock212 | HH3: Stock213 | HI3: Stock214 | HJ3: Stock215 | HK3: Stock216 | HL3: Stock217 | HM3: Stock218 | HN3: Stock219 | HO3: Stock220 | HP3: Stock221 | HQ3: Stock222 | HR3: Stock223 | HS3: Stock224 | HT3: Stock225 | HU3: Stock226 | HV3: Stock227 | HW3: Stock228 | HX3: Stock229 | HY3: Stock230 | HZ3: Stock231 | IA3: Stock232 | IB3: Stock233 | IC3: Stock234 | ID3: Stock235 | IE3: Stock236 | IF3: Stock237 | IG3: Stock238 | IH3: Stock239 | II3: Stock240 | IJ3: Stock241 | IK3: Stock242 | IL3: Stock243 | IM3: Stock244 | IN3: Stock245 | IO3: Stock246 | IP3: Stock247 | IQ3: Stock248 | IR3: Stock249 | IS3: Stock250
B4: Nifty 50 R % | D4: Stock R % | E4: Stock R % | F4: Stock R % | G4: Stock R % | H4: Stock R % | I4: Stock R % | J4: Stock R % | K4: Stock R % | L4: Stock R % | M4: Stock R % | N4: Stock R % | O4: Stock R % | P4: Stock R % | Q4: Stock R % | R4: Stock R % | S4: Stock R % | T4: Stock R % | U4: Stock R % | V4: Stock R % | W4: Stock R % | X4: Stock R % | Y4: Stock R % | Z4: Stock R % | AA4: Stock R % | AB4: Stock R % | AC4: Stock R % | AD4: Stock R % | AE4: Stock R % | AF4: Stock R % | AG4: Stock R % | AH4: Stock R % | AI4: Stock R % | AJ4: Stock R % | AK4: Stock R % | AL4: Stock R % | AM4: Stock R % | AN4: Stock R % | AO4: Stock R % | AP4: Stock R % | AQ4: Stock R % | AR4: Stock R % | AS4: Stock R % | AT4: Stock R % | AU4: Stock R % | AV4: Stock R % | AW4: Stock R % | AX4: Stock R % | AY4: Stock R % | AZ4: Stock R % | BA4: Stock R % | BB4: Stock R % | BC4: Stock R % | BD4: Stock R % | BE4: Stock R % | BF4: Stock R % | BG4: Stock R % | BH4: Stock R % | BI4: Stock R % | BJ4: Stock R % | BK4: Stock R % | BL4: Stock R % | BM4: Stock R % | BN4: Stock R % | BO4: Stock R % | BP4: Stock R % | BQ4: Stock R % | BR4: Stock R % | BS4: Stock R % | BT4: Stock R % | BU4: Stock R % | BV4: Stock R % | BW4: Stock R % | BX4: Stock R % | BY4: Stock R % | BZ4: Stock R % | CA4: Stock R % | CB4: Stock R % | CC4: Stock R % | CD4: Stock R % | CE4: Stock R % | CF4: Stock R % | CG4: Stock R % | CH4: Stock R % | CI4: Stock R % | CJ4: Stock R % | CK4: Stock R % | CL4: Stock R % | CM4: Stock R % | CN4: Stock R % | CO4: Stock R % | CP4: Stock R % | CQ4: Stock R % | CR4: Stock R % | CS4: Stock R % | CT4: Stock R % | CU4: Stock R % | CV4: Stock R % | CW4: Stock R % | CX4: Stock R % | CY4: Stock R % | CZ4: Stock R % | DA4: Stock R % | DB4: Stock R % | DC4: Stock R % | DD4: Stock R % | DE4: Stock R % | DF4: Stock R % | DG4: Stock R % | DH4: Stock R % | DI4: Stock R % | DJ4: Stock R % | DK4: Stock R % | DL4: Stock R % | DM4: Stock R % | DN4: Stock R % | DO4: Stock R % | DP4: Stock R % | DQ4: Stock R % | DR4: Stock R % | DS4: Stock R % | DT4: Stock R % | DU4: Stock R % | DV4: Stock R % | DW4: Stock R % | DX4: Stock R % | DY4: Stock R % | DZ4: Stock R % | EA4: Stock R % | EB4: Stock R % | EC4: Stock R % | ED4: Stock R % | EE4: Stock R % | EF4: Stock R % | EG4: Stock R % | EH4: Stock R % | EI4: Stock R % | EJ4: Stock R % | EK4: Stock R % | EL4: Stock R % | EM4: Stock R % | EN4: Stock R % | EO4: Stock R % | EP4: Stock R % | EQ4: Stock R % | ER4: Stock R % | ES4: Stock R % | ET4: Stock R % | EU4: Stock R % | EV4: Stock R % | EW4: Stock R % | EX4: Stock R % | EY4: Stock R % | EZ4: Stock R % | FA4: Stock R % | FB4: Stock R % | FC4: Stock R % | FD4: Stock R % | FE4: Stock R % | FF4: Stock R % | FG4: Stock R % | FH4: Stock R % | FI4: Stock R % | FJ4: Stock R % | FK4: Stock R % | FL4: Stock R % | FM4: Stock R % | FN4: Stock R % | FO4: Stock R % | FP4: Stock R % | FQ4: Stock R % | FR4: Stock R % | FS4: Stock R % | FT4: Stock R % | FU4: Stock R % | FV4: Stock R % | FW4: Stock R % | FX4: Stock R % | FY4: Stock R % | FZ4: Stock R % | GA4: Stock R % | GB4: Stock R % | GC4: Stock R % | GD4: Stock R % | GE4: Stock R % | GF4: Stock R % | GG4: Stock R % | GH4: Stock R % | GI4: Stock R % | GJ4: Stock R % | GK4: Stock R % | GL4: Stock R % | GM4: Stock R % | GN4: Stock R % | GO4: Stock R % | GP4: Stock R % | GQ4: Stock R % | GR4: Stock R % | GS4: Stock R % | GT4: Stock R % | GU4: Stock R % | GV4: Stock R % | GW4: Stock R % | GX4: Stock R % | GY4: Stock R % | GZ4: Stock R % | HA4: Stock R % | HB4: Stock R % | HC4: Stock R % | HD4: Stock R % | HE4: Stock R % | HF4: Stock R % | HG4: Stock R % | HH4: Stock R % | HI4: Stock R % | HJ4: Stock R % | HK4: Stock R % | HL4: Stock R % | HM4: Stock R % | HN4: Stock R % | HO4: Stock R % | HP4: Stock R % | HQ4: Stock R % | HR4: Stock R % | HS4: Stock R % | HT4: Stock R % | HU4: Stock R % | HV4: Stock R % | HW4: Stock R % | HX4: Stock R % | HY4: Stock R % | HZ4: Stock R % | IA4: Stock R % | IB4: Stock R % | IC4: Stock R % | ID4: Stock R % | IE4: Stock R % | IF4: Stock R % | IG4: Stock R % | IH4: Stock R % | II4: Stock R % | IJ4: Stock R % | IK4: Stock R % | IL4: Stock R % | IM4: Stock R % | IN4: Stock R % | IO4: Stock R % | IP4: Stock R % | IQ4: Stock R % | IR4: Stock R % | IS4: Stock R %
B5: =(BETA_DATA!C5-BETA_DATA!C6)/BETA_DATA!C6 -> #N/A | D5: =(BETA_DATA!E5-BETA_DATA!E6)/BETA_DATA!E6 -> #N/A | E5: =(BETA_DATA!F5-BETA_DATA!F6)/BETA_DATA!F6 -> #N/A | F5: =(BETA_DATA!G5-BETA_DATA!G6)/BETA_DATA!G6 -> #N/A | G5: =(BETA_DATA!H5-BETA_DATA!H6)/BETA_DATA!H6 -> #N/A | H5: =(BETA_DATA!I5-BETA_DATA!I6)/BETA_DATA!I6 -> #N/A | I5: =(BETA_DATA!J5-BETA_DATA!J6)/BETA_DATA!J6 -> #DIV/0! | J5: =(BETA_DATA!K5-BETA_DATA!K6)/BETA_DATA!K6 -> #DIV/0! | K5: =(BETA_DATA!L5-BETA_DATA!L6)/BETA_DATA!L6 -> #DIV/0! | ... IS5: =(BETA_DATA!IT5-BETA_DATA!IT6)/BETA_DATA!IT6 -> #DIV/0!
B6: =(BETA_DATA!C6-BETA_DATA!C7)/BETA_DATA!C7 -> #N/A | D6: =(BETA_DATA!E6-BETA_DATA!E7)/BETA_DATA!E7 -> #N/A | E6: =(BETA_DATA!F6-BETA_DATA!F7)/BETA_DATA!F7 -> #N/A | F6: =(BETA_DATA!G6-BETA_DATA!G7)/BETA_DATA!G7 -> #N/A | G6: =(BETA_DATA!H6-BETA_DATA!H7)/BETA_DATA!H7 -> #N/A | H6: =(BETA_DATA!I6-BETA_DATA!I7)/BETA_DATA!I7 -> #N/A | I6: =(BETA_DATA!J6-BETA_DATA!J7)/BETA_DATA!J7 -> #DIV/0! | J6: =(BETA_DATA!K6-BETA_DATA!K7)/BETA_DATA!K7 -> #DIV/0! | K6: =(BETA_DATA!L6-BETA_DATA!L7)/BETA_DATA!L7 -> #DIV/0! | ... IS6: =(BETA_DATA!IT6-BETA_DATA!IT7)/BETA_DATA!IT7 -> #DIV/0!
B7: =(BETA_DATA!C7-BETA_DATA!C8)/BETA_DATA!C8 -> 0.0053628888 | D7: =(BETA_DATA!E7-BETA_DATA!E8)/BETA_DATA!E8 -> #N/A | E7: =(BETA_DATA!F7-BETA_DATA!F8)/BETA_DATA!F8 -> #N/A | F7: =(BETA_DATA!G7-BETA_DATA!G8)/BETA_DATA!G8 -> #N/A | G7: =(BETA_DATA!H7-BETA_DATA!H8)/BETA_DATA!H8 -> #N/A | H7: =(BETA_DATA!I7-BETA_DATA!I8)/BETA_DATA!I8 -> #N/A | I7: =(BETA_DATA!J7-BETA_DATA!J8)/BETA_DATA!J8 -> #DIV/0! | J7: =(BETA_DATA!K7-BETA_DATA!K8)/BETA_DATA!K8 -> #DIV/0! | K7: =(BETA_DATA!L7-BETA_DATA!L8)/BETA_DATA!L8 -> #DIV/0! | ... IS7: =(BETA_DATA!IT7-BETA_DATA!IT8)/BETA_DATA!IT8 -> #DIV/0!
B8: =(BETA_DATA!C8-BETA_DATA!C9)/BETA_DATA!C9 -> 0.0096753509 | D8: =(BETA_DATA!E8-BETA_DATA!E9)/BETA_DATA!E9 -> #N/A | E8: =(BETA_DATA!F8-BETA_DATA!F9)/BETA_DATA!F9 -> #N/A | F8: =(BETA_DATA!G8-BETA_DATA!G9)/BETA_DATA!G9 -> #N/A | G8: =(BETA_DATA!H8-BETA_DATA!H9)/BETA_DATA!H9 -> #N/A | H8: =(BETA_DATA!I8-BETA_DATA!I9)/BETA_DATA!I9 -> #N/A | I8: =(BETA_DATA!J8-BETA_DATA!J9)/BETA_DATA!J9 -> #DIV/0! | J8: =(BETA_DATA!K8-BETA_DATA!K9)/BETA_DATA!K9 -> #DIV/0! | K8: =(BETA_DATA!L8-BETA_DATA!L9)/BETA_DATA!L9 -> #DIV/0! | ... IS8: =(BETA_DATA!IT8-BETA_DATA!IT9)/BETA_DATA!IT9 -> #DIV/0!
B9: =(BETA_DATA!C9-BETA_DATA!C10)/BETA_DATA!C10 -> -0.0069150617 | D9: =(BETA_DATA!E9-BETA_DATA!E10)/BETA_DATA!E10 -> #N/A | E9: =(BETA_DATA!F9-BETA_DATA!F10)/BETA_DATA!F10 -> #N/A | F9: =(BETA_DATA!G9-BETA_DATA!G10)/BETA_DATA!G10 -> #N/A | G9: =(BETA_DATA!H9-BETA_DATA!H10)/BETA_DATA!H10 -> #N/A | H9: =(BETA_DATA!I9-BETA_DATA!I10)/BETA_DATA!I10 -> #N/A | I9: =(BETA_DATA!J9-BETA_DATA!J10)/BETA_DATA!J10 -> #DIV/0! | J9: =(BETA_DATA!K9-BETA_DATA!K10)/BETA_DATA!K10 -> #DIV/0! | K9: =(BETA_DATA!L9-BETA_DATA!L10)/BETA_DATA!L10 -> #DIV/0! | ... IS9: =(BETA_DATA!IT9-BETA_DATA!IT10)/BETA_DATA!IT10 -> #DIV/0!
B10: =(BETA_DATA!C10-BETA_DATA!C11)/BETA_DATA!C11 -> -0.0052692329 | D10: =(BETA_DATA!E10-BETA_DATA!E11)/BETA_DATA!E11 -> #N/A | E10: =(BETA_DATA!F10-BETA_DATA!F11)/BETA_DATA!F11 -> #N/A | F10: =(BETA_DATA!G10-BETA_DATA!G11)/BETA_DATA!G11 -> #N/A | G10: =(BETA_DATA!H10-BETA_DATA!H11)/BETA_DATA!H11 -> #N/A | H10: =(BETA_DATA!I10-BETA_DATA!I11)/BETA_DATA!I11 -> #N/A | I10: =(BETA_DATA!J10-BETA_DATA!J11)/BETA_DATA!J11 -> #DIV/0! | J10: =(BETA_DATA!K10-BETA_DATA!K11)/BETA_DATA!K11 -> #DIV/0! | K10: =(BETA_DATA!L10-BETA_DATA!L11)/BETA_DATA!L11 -> #DIV/0! | ... IS10: =(BETA_DATA!IT10-BETA_DATA!IT11)/BETA_DATA!IT11 -> #DIV/0!
B11: =(BETA_DATA!C11-BETA_DATA!C12)/BETA_DATA!C12 -> -0.0099596782 | D11: =(BETA_DATA!E11-BETA_DATA!E12)/BETA_DATA!E12 -> #N/A | E11: =(BETA_DATA!F11-BETA_DATA!F12)/BETA_DATA!F12 -> #N/A | F11: =(BETA_DATA!G11-BETA_DATA!G12)/BETA_DATA!G12 -> #N/A | G11: =(BETA_DATA!H11-BETA_DATA!H12)/BETA_DATA!H12 -> #N/A | H11: =(BETA_DATA!I11-BETA_DATA!I12)/BETA_DATA!I12 -> #N/A | I11: =(BETA_DATA!J11-BETA_DATA!J12)/BETA_DATA!J12 -> #DIV/0! | J11: =(BETA_DATA!K11-BETA_DATA!K12)/BETA_DATA!K12 -> #DIV/0! | K11: =(BETA_DATA!L11-BETA_DATA!L12)/BETA_DATA!L12 -> #DIV/0! | ... IS11: =(BETA_DATA!IT11-BETA_DATA!IT12)/BETA_DATA!IT12 -> #DIV/0!
B12: =(BETA_DATA!C12-BETA_DATA!C13)/BETA_DATA!C13 -> 0.0076014304 | D12: =(BETA_DATA!E12-BETA_DATA!E13)/BETA_DATA!E13 -> #N/A | E12: =(BETA_DATA!F12-BETA_DATA!F13)/BETA_DATA!F13 -> #N/A | F12: =(BETA_DATA!G12-BETA_DATA!G13)/BETA_DATA!G13 -> #N/A | G12: =(BETA_DATA!H12-BETA_DATA!H13)/BETA_DATA!H13 -> #N/A | H12: =(BETA_DATA!I12-BETA_DATA!I13)/BETA_DATA!I13 -> #N/A | I12: =(BETA_DATA!J12-BETA_DATA!J13)/BETA_DATA!J13 -> #DIV/0! | J12: =(BETA_DATA!K12-BETA_DATA!K13)/BETA_DATA!K13 -> #DIV/0! | K12: =(BETA_DATA!L12-BETA_DATA!L13)/BETA_DATA!L13 -> #DIV/0! | ... IS12: =(BETA_DATA!IT12-BETA_DATA!IT13)/BETA_DATA!IT13 -> #DIV/0!
B13: =(BETA_DATA!C13-BETA_DATA!C14)/BETA_DATA!C14 -> 0.0061695254 | D13: =(BETA_DATA!E13-BETA_DATA!E14)/BETA_DATA!E14 -> #N/A | E13: =(BETA_DATA!F13-BETA_DATA!F14)/BETA_DATA!F14 -> #N/A | F13: =(BETA_DATA!G13-BETA_DATA!G14)/BETA_DATA!G14 -> #N/A | G13: =(BETA_DATA!H13-BETA_DATA!H14)/BETA_DATA!H14 -> #N/A | H13: =(BETA_DATA!I13-BETA_DATA!I14)/BETA_DATA!I14 -> #N/A | I13: =(BETA_DATA!J13-BETA_DATA!J14)/BETA_DATA!J14 -> #DIV/0! | J13: =(BETA_DATA!K13-BETA_DATA!K14)/BETA_DATA!K14 -> #DIV/0! | K13: =(BETA_DATA!L13-BETA_DATA!L14)/BETA_DATA!L14 -> #DIV/0! | ... IS13: =(BETA_DATA!IT13-BETA_DATA!IT14)/BETA_DATA!IT14 -> #DIV/0!
B14: =(BETA_DATA!C14-BETA_DATA!C15)/BETA_DATA!C15 -> 0.0038198614 | D14: =(BETA_DATA!E14-BETA_DATA!E15)/BETA_DATA!E15 -> #N/A | E14: =(BETA_DATA!F14-BETA_DATA!F15)/BETA_DATA!F15 -> #N/A | F14: =(BETA_DATA!G14-BETA_DATA!G15)/BETA_DATA!G15 -> #N/A | G14: =(BETA_DATA!H14-BETA_DATA!H15)/BETA_DATA!H15 -> #N/A | H14: =(BETA_DATA!I14-BETA_DATA!I15)/BETA_DATA!I15 -> #N/A | I14: =(BETA_DATA!J14-BETA_DATA!J15)/BETA_DATA!J15 -> #DIV/0! | J14: =(BETA_DATA!K14-BETA_DATA!K15)/BETA_DATA!K15 -> #DIV/0! | K14: =(BETA_DATA!L14-BETA_DATA!L15)/BETA_DATA!L15 -> #DIV/0! | ... IS14: =(BETA_DATA!IT14-BETA_DATA!IT15)/BETA_DATA!IT15 -> #DIV/0!
B15: =(BETA_DATA!C15-BETA_DATA!C16)/BETA_DATA!C16 -> -0.0005858729 | D15: =(BETA_DATA!E15-BETA_DATA!E16)/BETA_DATA!E16 -> #N/A | E15: =(BETA_DATA!F15-BETA_DATA!F16)/BETA_DATA!F16 -> #N/A | F15: =(BETA_DATA!G15-BETA_DATA!G16)/BETA_DATA!G16 -> #N/A | G15: =(BETA_DATA!H15-BETA_DATA!H16)/BETA_DATA!H16 -> #N/A | H15: =(BETA_DATA!I15-BETA_DATA!I16)/BETA_DATA!I16 -> #N/A | I15: =(BETA_DATA!J15-BETA_DATA!J16)/BETA_DATA!J16 -> #DIV/0! | J15: =(BETA_DATA!K15-BETA_DATA!K16)/BETA_DATA!K16 -> #DIV/0! | K15: =(BETA_DATA!L15-BETA_DATA!L16)/BETA_DATA!L16 -> #DIV/0! | ... IS15: =(BETA_DATA!IT15-BETA_DATA!IT16)/BETA_DATA!IT16 -> #DIV/0!
B16: =(BETA_DATA!C16-BETA_DATA!C17)/BETA_DATA!C17 -> 0.009568602 | D16: =(BETA_DATA!E16-BETA_DATA!E17)/BETA_DATA!E17 -> #N/A | E16: =(BETA_DATA!F16-BETA_DATA!F17)/BETA_DATA!F17 -> #N/A | F16: =(BETA_DATA!G16-BETA_DATA!G17)/BETA_DATA!G17 -> #N/A | G16: =(BETA_DATA!H16-BETA_DATA!H17)/BETA_DATA!H17 -> #N/A | H16: =(BETA_DATA!I16-BETA_DATA!I17)/BETA_DATA!I17 -> #N/A | I16: =(BETA_DATA!J16-BETA_DATA!J17)/BETA_DATA!J17 -> #DIV/0! | J16: =(BETA_DATA!K16-BETA_DATA!K17)/BETA_DATA!K17 -> #DIV/0! | K16: =(BETA_DATA!L16-BETA_DATA!L17)/BETA_DATA!L17 -> #DIV/0! | ... IS16: =(BETA_DATA!IT16-BETA_DATA!IT17)/BETA_DATA!IT17 -> #DIV/0!
... B251: =(BETA_DATA!C251-BETA_DATA!C252)/BETA_DATA!C252 -> -0.00086304573 | D251: =(BETA_DATA!E251-BETA_DATA!E252)/BETA_DATA!E252 -> 0.00062497396 | E251: =(BETA_DATA!F251-BETA_DATA!F252)/BETA_DATA!F252 -> -0.007997936 | F251: =(BETA_DATA!G251-BETA_DATA!G252)/BETA_DATA!G252 -> 0.0066206897 | G251: =(BETA_DATA!H251-BETA_DATA!H252)/BETA_DATA!H252 -> -0.0046893318 | H251: =(BETA_DATA!I251-BETA_DATA!I252)/BETA_DATA!I252 -> -0.0093373494 | I251: =(BETA_DATA!J251-BETA_DATA!J252)/BETA_DATA!J252 -> #DIV/0! | J251: =(BETA_DATA!K251-BETA_DATA!K252)/BETA_DATA!K252 -> #DIV/0! | K251: =(BETA_DATA!L251-BETA_DATA!L252)/BETA_DATA!L252 -> #DIV/0! | ... IS251: =(BETA_DATA!IT251-BETA_DATA!IT252)/BETA_DATA!IT252 -> #DIV/0!

Sheet BETA_DATA
Y1: Nifty 50 | Z1: https://www.nseindia.com/products/content/equities/indices/historical_index_data.htm
Y2: Stock Data | Z2: https://www.nseindia.com/products/content/equities/equities/eq_security.htm
B3: =CONCATENATE("Beta Calculation") -> Beta Calculation
B4: Date | C4: Nifty 50 | E4: Stock1 | F4: Stock2 | G4: Stock3 | H4: Stock4 | I4: Stock5 | J4: Stock6 | K4: Stock7 | L4: Stock8 | M4: Stock9 | N4: Stock10 | O4: Stock11 | P4: Stock12 | Q4: Stock13 | R4: Stock14 | S4: Stock15 | T4: Stock16 | U4: Stock17 | V4: Stock18 | W4: Stock19 | X4: Stock20 | Y4: Stock21 | Z4: Stock22 | AA4: Stock23 | AB4: Stock24 | AC4: Stock25 | AD4: Stock26 | AE4: Stock27 | AF4: Stock28 | AG4: Stock29 | AH4: Stock30 | AI4: Stock31 | AJ4: Stock32 | AK4: Stock33 | AL4: Stock34 | AM4: Stock35 | AN4: Stock36 | AO4: Stock37 | AP4: Stock38 | AQ4: Stock39 | AR4: Stock40 | AS4: Stock41 | AT4: Stock42 | AU4: Stock43 | AV4: Stock44 | AW4: Stock45 | AX4: Stock46 | AY4: Stock47 | AZ4: Stock48 | BA4: Stock49 | BB4: Stock50 | BC4: Stock51 | BD4: Stock52 | BE4: Stock53 | BF4: Stock54 | BG4: Stock55 | BH4: Stock56 | BI4: Stock57 | BJ4: Stock58 | BK4: Stock59 | BL4: Stock60 | BM4: Stock61 | BN4: Stock62 | BO4: Stock63 | BP4: Stock64 | BQ4: Stock65 | BR4: Stock66 | BS4: Stock67 | BT4: Stock68 | BU4: Stock69 | BV4: Stock70 | BW4: Stock71 | BX4: Stock72 | BY4: Stock73 | BZ4: Stock74 | CA4: Stock75 | CB4: Stock76 | CC4: Stock77 | CD4: Stock78 | CE4: Stock79 | CF4: Stock80 | CG4: Stock81 | CH4: Stock82 | CI4: Stock83 | CJ4: Stock84 | CK4: Stock85 | CL4: Stock86 | CM4: Stock87 | CN4: Stock88 | CO4: Stock89 | CP4: Stock90 | CQ4: Stock91 | CR4: Stock92 | CS4: Stock93 | CT4: Stock94 | CU4: Stock95 | CV4: Stock96 | CW4: Stock97 | CX4: Stock98 | CY4: Stock99 | CZ4: Stock100 | DA4: Stock101 | DB4: Stock102 | DC4: Stock103 | DD4: Stock104 | DE4: Stock105 | DF4: Stock106 | DG4: Stock107 | DH4: Stock108 | DI4: Stock109 | DJ4: Stock110 | DK4: Stock111 | DL4: Stock112 | DM4: Stock113 | DN4: Stock114 | DO4: Stock115 | DP4: Stock116 | DQ4: Stock117 | DR4: Stock118 | DS4: Stock119 | DT4: Stock120 | DU4: Stock121 | DV4: Stock122 | DW4: Stock123 | DX4: Stock124 | DY4: Stock125 | DZ4: Stock126 | EA4: Stock127 | EB4: Stock128 | EC4: Stock129 | ED4: Stock130 | EE4: Stock131 | EF4: Stock132 | EG4: Stock133 | EH4: Stock134 | EI4: Stock135 | EJ4: Stock136 | EK4: Stock137 | EL4: Stock138 | EM4: Stock139 | EN4: Stock140 | EO4: Stock141 | EP4: Stock142 | EQ4: Stock143 | ER4: Stock144 | ES4: Stock145 | ET4: Stock146 | EU4: Stock147 | EV4: Stock148 | EW4: Stock149 | EX4: Stock150 | EY4: Stock151 | EZ4: Stock152 | FA4: Stock153 | FB4: Stock154 | FC4: Stock155 | FD4: Stock156 | FE4: Stock157 | FF4: Stock158 | FG4: Stock159 | FH4: Stock160 | FI4: Stock161 | FJ4: Stock162 | FK4: Stock163 | FL4: Stock164 | FM4: Stock165 | FN4: Stock166 | FO4: Stock167 | FP4: Stock168 | FQ4: Stock169 | FR4: Stock170 | FS4: Stock171 | FT4: Stock172 | FU4: Stock173 | FV4: Stock174 | FW4: Stock175 | FX4: Stock176 | FY4: Stock177 | FZ4: Stock178 | GA4: Stock179 | GB4: Stock180 | GC4: Stock181 | GD4: Stock182 | GE4: Stock183 | GF4: Stock184 | GG4: Stock185 | GH4: Stock186 | GI4: Stock187 | GJ4: Stock188 | GK4: Stock189 | GL4: Stock190 | GM4: Stock191 | GN4: Stock192 | GO4: Stock193 | GP4: Stock194 | GQ4: Stock195 | GR4: Stock196 | GS4: Stock197 | GT4: Stock198 | GU4: Stock199 | GV4: Stock200 | GW4: Stock201 | GX4: Stock202 | GY4: Stock203 | GZ4: Stock204 | HA4: Stock205 | HB4: Stock206 | HC4: Stock207 | HD4: Stock208 | HE4: Stock209 | HF4: Stock210 | HG4: Stock211 | HH4: Stock212 | HI4: Stock213 | HJ4: Stock214 | HK4: Stock215 | HL4: Stock216 | HM4: Stock217 | HN4: Stock218 | HO4: Stock219 | HP4: Stock220 | HQ4: Stock221 | HR4: Stock222 | HS4: Stock223 | HT4: Stock224 | HU4: Stock225 | HV4: Stock226 | HW4: Stock227 | HX4: Stock228 | HY4: Stock229 | HZ4: Stock230 | IA4: Stock231 | IB4: Stock232 | IC4: Stock233 | ID4: Stock234 | IE4: Stock235 | IF4: Stock236 | IG4: Stock237 | IH4: Stock238 | II4: Stock239 | IJ4: Stock240 | IK4: Stock241 | IL4: Stock242 | IM4: Stock243 | IN4: Stock244 | IO4: Stock245 | IP4: Stock246 | IQ4: Stock247 | IR4: Stock248 | IS4: Stock249 | IT4: Stock250
B5: =NIFTY50!A249 -> 0 | C5: =VLOOKUP(B5,NIFTY50!$A:$G,5,0) -> #N/A | E5: =VLOOKUP($B5,'STOCK (1)'!$C:$O,7,0) -> #N/A | F5: =VLOOKUP($B5,'STOCK (2)'!$C:$O,7,0) -> #N/A | G5: =VLOOKUP($B5,'STOCK (3)'!$C:$O,7,0) -> #N/A | H5: =VLOOKUP($B5,'STOCK (4)'!$C:$O,7,0) -> #N/A | I5: =VLOOKUP($B5,'STOCK (5)'!$C:$O,7,0) -> #N/A
B6: =NIFTY50!A248 -> 0 | C6: =VLOOKUP(B6,NIFTY50!$A:$G,5,0) -> #N/A | E6: =VLOOKUP($B6,'STOCK (1)'!$C:$O,7,0) -> #N/A | F6: =VLOOKUP($B6,'STOCK (2)'!$C:$O,7,0) -> #N/A | G6: =VLOOKUP($B6,'STOCK (3)'!$C:$O,7,0) -> #N/A | H6: =VLOOKUP($B6,'STOCK (4)'!$C:$O,7,0) -> #N/A | I6: =VLOOKUP($B6,'STOCK (5)'!$C:$O,7,0) -> #N/A
B7: =NIFTY50!A247 -> 43431 | C7: =VLOOKUP(B7,NIFTY50!$A:$G,5,0) -> 10685.6 | E7: =VLOOKUP($B7,'STOCK (1)'!$C:$O,7,0) -> #N/A | F7: =VLOOKUP($B7,'STOCK (2)'!$C:$O,7,0) -> #N/A | G7: =VLOOKUP($B7,'STOCK (3)'!$C:$O,7,0) -> #N/A | H7: =VLOOKUP($B7,'STOCK (4)'!$C:$O,7,0) -> #N/A | I7: =VLOOKUP($B7,'STOCK (5)'!$C:$O,7,0) -> #N/A
B8: =NIFTY50!A246 -> 43430 | C8: =VLOOKUP(B8,NIFTY50!$A:$G,5,0) -> 10628.6 | E8: =VLOOKUP($B8,'STOCK (1)'!$C:$O,7,0) -> #N/A | F8: =VLOOKUP($B8,'STOCK (2)'!$C:$O,7,0) -> #N/A | G8: =VLOOKUP($B8,'STOCK (3)'!$C:$O,7,0) -> #N/A | H8: =VLOOKUP($B8,'STOCK (4)'!$C:$O,7,0) -> #N/A | I8: =VLOOKUP($B8,'STOCK (5)'!$C:$O,7,0) -> #N/A
B9: =NIFTY50!A245 -> 43426 | C9: =VLOOKUP(B9,NIFTY50!$A:$G,5,0) -> 10526.75 | E9: =VLOOKUP($B9,'STOCK (1)'!$C:$O,7,0) -> #N/A | F9: =VLOOKUP($B9,'STOCK (2)'!$C:$O,7,0) -> #N/A | G9: =VLOOKUP($B9,'STOCK (3)'!$C:$O,7,0) -> #N/A | H9: =VLOOKUP($B9,'STOCK (4)'!$C:$O,7,0) -> #N/A | I9: =VLOOKUP($B9,'STOCK (5)'!$C:$O,7,0) -> #N/A
B10: =NIFTY50!A244 -> 43425 | C10: =VLOOKUP(B10,NIFTY50!$A:$G,5,0) -> 10600.05 | E10: =VLOOKUP($B10,'STOCK (1)'!$C:$O,7,0) -> #N/A | F10: =VLOOKUP($B10,'STOCK (2)'!$C:$O,7,0) -> #N/A | G10: =VLOOKUP($B10,'STOCK (3)'!$C:$O,7,0) -> #N/A | H10: =VLOOKUP($B10,'STOCK (4)'!$C:$O,7,0) -> #N/A | I10: =VLOOKUP($B10,'STOCK (5)'!$C:$O,7,0) -> #N/A
B11: =NIFTY50!A243 -> 43424 | C11: =VLOOKUP(B11,NIFTY50!$A:$G,5,0) -> 10656.2 | E11: =VLOOKUP($B11,'STOCK (1)'!$C:$O,7,0) -> #N/A | F11: =VLOOKUP($B11,'STOCK (2)'!$C:$O,7,0) -> #N/A | G11: =VLOOKUP($B11,'STOCK (3)'!$C:$O,7,0) -> #N/A | H11: =VLOOKUP($B11,'STOCK (4)'!$C:$O,7,0) -> #N/A | I11: =VLOOKUP($B11,'STOCK (5)'!$C:$O,7,0) -> #N/A
B12: =NIFTY50!A242 -> 43423 | C12: =VLOOKUP(B12,NIFTY50!$A:$G,5,0) -> 10763.4 | E12: =VLOOKUP($B12,'STOCK (1)'!$C:$O,7,0) -> #N/A | F12: =VLOOKUP($B12,'STOCK (2)'!$C:$O,7,0) -> #N/A | G12: =VLOOKUP($B12,'STOCK (3)'!$C:$O,7,0) -> #N/A | H12: =VLOOKUP($B12,'STOCK (4)'!$C:$O,7,0) -> #N/A | I12: =VLOOKUP($B12,'STOCK (5)'!$C:$O,7,0) -> #N/A
B13: =NIFTY50!A241 -> 43420 | C13: =VLOOKUP(B13,NIFTY50!$A:$G,5,0) -> 10682.2 | E13: =VLOOKUP($B13,'STOCK (1)'!$C:$O,7,0) -> #N/A | F13: =VLOOKUP($B13,'STOCK (2)'!$C:$O,7,0) -> #N/A | G13: =VLOOKUP($B13,'STOCK (3)'!$C:$O,7,0) -> #N/A | H13: =VLOOKUP($B13,'STOCK (4)'!$C:$O,7,0) -> #N/A | I13: =VLOOKUP($B13,'STOCK (5)'!$C:$O,7,0) -> #N/A
B14: =NIFTY50!A240 -> 43419 | C14: =VLOOKUP(B14,NIFTY50!$A:$G,5,0) -> 10616.7 | E14: =VLOOKUP($B14,'STOCK (1)'!$C:$O,7,0) -> #N/A | F14: =VLOOKUP($B14,'STOCK (2)'!$C:$O,7,0) -> #N/A | G14: =VLOOKUP($B14,'STOCK (3)'!$C:$O,7,0) -> #N/A | H14: =VLOOKUP($B14,'STOCK (4)'!$C:$O,7,0) -> #N/A | I14: =VLOOKUP($B14,'STOCK (5)'!$C:$O,7,0) -> #N/A
B15: =NIFTY50!A239 -> 43418 | C15: =VLOOKUP(B15,NIFTY50!$A:$G,5,0) -> 10576.3 | E15: =VLOOKUP($B15,'STOCK (1)'!$C:$O,7,0) -> #N/A | F15: =VLOOKUP($B15,'STOCK (2)'!$C:$O,7,0) -> #N/A | G15: =VLOOKUP($B15,'STOCK (3)'!$C:$O,7,0) -> #N/A | H15: =VLOOKUP($B15,'STOCK (4)'!$C:$O,7,0) -> #N/A | I15: =VLOOKUP($B15,'STOCK (5)'!$C:$O,7,0) -> #N/A
B16: =NIFTY50!A238 -> 43417 | C16: =VLOOKUP(B16,NIFTY50!$A:$G,5,0) -> 10582.5 | E16: =VLOOKUP($B16,'STOCK (1)'!$C:$O,7,0) -> #N/A | F16: =VLOOKUP($B16,'STOCK (2)'!$C:$O,7,0) -> #N/A | G16: =VLOOKUP($B16,'STOCK (3)'!$C:$O,7,0) -> #N/A | H16: =VLOOKUP($B16,'STOCK (4)'!$C:$O,7,0) -> #N/A | I16: =VLOOKUP($B16,'STOCK (5)'!$C:$O,7,0) -> #N/A
B17: =NIFTY50!A237 -> 43416 | C17: =VLOOKUP(B17,NIFTY50!$A:$G,5,0) -> 10482.2 | E17: =VLOOKUP($B17,'STOCK (1)'!$C:$O,7,0) -> #N/A | F17: =VLOOKUP($B17,'STOCK (2)'!$C:$O,7,0) -> #N/A | G17: =VLOOKUP($B17,'STOCK (3)'!$C:$O,7,0) -> #N/A | H17: =VLOOKUP($B17,'STOCK (4)'!$C:$O,7,0) -> #N/A | I17: =VLOOKUP($B17,'STOCK (5)'!$C:$O,7,0) -> #N/A
B18: =NIFTY50!A236 -> 43413 | C18: =VLOOKUP(B18,NIFTY50!$A:$G,5,0) -> 10585.2 | E18: =VLOOKUP($B18,'STOCK (1)'!$C:$O,7,0) -> #N/A | F18: =VLOOKUP($B18,'STOCK (2)'!$C:$O,7,0) -> #N/A | G18: =VLOOKUP($B18,'STOCK (3)'!$C:$O,7,0) -> #N/A | H18: =VLOOKUP($B18,'STOCK (4)'!$C:$O,7,0) -> #N/A | I18: =VLOOKUP($B18,'STOCK (5)'!$C:$O,7,0) -> #N/A
B19: =NIFTY50!A235 -> 43411 | C19: =VLOOKUP(B19,NIFTY50!$A:$G,5,0) -> 10598.4 | E19: =VLOOKUP($B19,'STOCK (1)'!$C:$O,7,0) -> #N/A | F19: =VLOOKUP($B19,'STOCK (2)'!$C:$O,7,0) -> #N/A | G19: =VLOOKUP($B19,'STOCK (3)'!$C:$O,7,0) -> #N/A | H19: =VLOOKUP($B19,'STOCK (4)'!$C:$O,7,0) -> #N/A | I19: =VLOOKUP($B19,'STOCK (5)'!$C:$O,7,0) -> #N/A
B20: =NIFTY50!A234 -> 43410 | C20: =VLOOKUP(B20,NIFTY50!$A:$G,5,0) -> 10530 | E20: =VLOOKUP($B20,'STOCK (1)'!$C:$O,7,0) -> #N/A | F20: =VLOOKUP($B20,'STOCK (2)'!$C:$O,7,0) -> #N/A | G20: =VLOOKUP($B20,'STOCK (3)'!$C:$O,7,0) -> #N/A | H20: =VLOOKUP($B20,'STOCK (4)'!$C:$O,7,0) -> #N/A | I20: =VLOOKUP($B20,'STOCK (5)'!$C:$O,7,0) -> #N/A
B21: =NIFTY50!A233 -> 43409 | C21: =VLOOKUP(B21,NIFTY50!$A:$G,5,0) -> 10524 | E21: =VLOOKUP($B21,'STOCK (1)'!$C:$O,7,0) -> #N/A | F21: =VLOOKUP($B21,'STOCK (2)'!$C:$O,7,0) -> #N/A | G21: =VLOOKUP($B21,'STOCK (3)'!$C:$O,7,0) -> #N/A | H21: =VLOOKUP($B21,'STOCK (4)'!$C:$O,7,0) -> #N/A | I21: =VLOOKUP($B21,'STOCK (5)'!$C:$O,7,0) -> #N/A
B22: =NIFTY50!A232 -> 43406 | C22: =VLOOKUP(B22,NIFTY50!$A:$G,5,0) -> 10553 | E22: =VLOOKUP($B22,'STOCK (1)'!$C:$O,7,0) -> #N/A | F22: =VLOOKUP($B22,'STOCK (2)'!$C:$O,7,0) -> #N/A | G22: =VLOOKUP($B22,'STOCK (3)'!$C:$O,7,0) -> #N/A | H22: =VLOOKUP($B22,'STOCK (4)'!$C:$O,7,0) -> #N/A | I22: =VLOOKUP($B22,'STOCK (5)'!$C:$O,7,0) -> #N/A
B23: =NIFTY50!A231 -> 43405 | C23: =VLOOKUP(B23,NIFTY50!$A:$G,5,0) -> 10380.45 | E23: =VLOOKUP($B23,'STOCK (1)'!$C:$O,7,0) -> #N/A | F23: =VLOOKUP($B23,'STOCK (2)'!$C:$O,7,0) -> #N/A | G23: =VLOOKUP($B23,'STOCK (3)'!$C:$O,7,0) -> #N/A | H23: =VLOOKUP($B23,'STOCK (4)'!$C:$O,7,0) -> #N/A | I23: =VLOOKUP($B23,'STOCK (5)'!$C:$O,7,0) -> #N/A
B24: =NIFTY50!A230 -> 43404 | C24: =VLOOKUP(B24,NIFTY50!$A:$G,5,0) -> 10386.6 | E24: =VLOOKUP($B24,'STOCK (1)'!$C:$O,7,0) -> #N/A | F24: =VLOOKUP($B24,'STOCK (2)'!$C:$O,7,0) -> #N/A | G24: =VLOOKUP($B24,'STOCK (3)'!$C:$O,7,0) -> #N/A | H24: =VLOOKUP($B24,'STOCK (4)'!$C:$O,7,0) -> #N/A | I24: =VLOOKUP($B24,'STOCK (5)'!$C:$O,7,0) -> #N/A
B25: =NIFTY50!A229 -> 43403 | C25: =VLOOKUP(B25,NIFTY50!$A:$G,5,0) -> 10198.4 | E25: =VLOOKUP($B25,'STOCK (1)'!$C:$O,7,0) -> #N/A | F25: =VLOOKUP($B25,'STOCK (2)'!$C:$O,7,0) -> #N/A | G25: =VLOOKUP($B25,'STOCK (3)'!$C:$O,7,0) -> #N/A | H25: =VLOOKUP($B25,'STOCK (4)'!$C:$O,7,0) -> #N/A | I25: =VLOOKUP($B25,'STOCK (5)'!$C:$O,7,0) -> #N/A
B26: =NIFTY50!A228 -> 43402 | C26: =VLOOKUP(B26,NIFTY50!$A:$G,5,0) -> 10250.85 | E26: =VLOOKUP($B26,'STOCK (1)'!$C:$O,7,0) -> #N/A | F26: =VLOOKUP($B26,'STOCK (2)'!$C:$O,7,0) -> #N/A | G26: =VLOOKUP($B26,'STOCK (3)'!$C:$O,7,0) -> #N/A | H26: =VLOOKUP($B26,'STOCK (4)'!$C:$O,7,0) -> #N/A | I26: =VLOOKUP($B26,'STOCK (5)'!$C:$O,7,0) -> #N/A
B27: =NIFTY50!A227 -> 43399 | C27: =VLOOKUP(B27,NIFTY50!$A:$G,5,0) -> 10030 | E27: =VLOOKUP($B27,'STOCK (1)'!$C:$O,7,0) -> #N/A | F27: =VLOOKUP($B27,'STOCK (2)'!$C:$O,7,0) -> #N/A | G27: =VLOOKUP($B27,'STOCK (3)'!$C:$O,7,0) -> #N/A | H27: =VLOOKUP($B27,'STOCK (4)'!$C:$O,7,0) -> #N/A | I27: =VLOOKUP($B27,'STOCK (5)'!$C:$O,7,0) -> #N/A
B28: =NIFTY50!A226 -> 43398 | C28: =VLOOKUP(B28,NIFTY50!$A:$G,5,0) -> 10124.9 | E28: =VLOOKUP($B28,'STOCK (1)'!$C:$O,7,0) -> #N/A | F28: =VLOOKUP($B28,'STOCK (2)'!$C:$O,7,0) -> #N/A | G28: =VLOOKUP($B28,'STOCK (3)'!$C:$O,7,0) -> #N/A | H28: =VLOOKUP($B28,'STOCK (4)'!$C:$O,7,0) -> #N/A | I28: =VLOOKUP($B28,'STOCK (5)'!$C:$O,7,0) -> #N/A
B29: =NIFTY50!A225 -> 43397 | C29: =VLOOKUP(B29,NIFTY50!$A:$G,5,0) -> 10224.75 | E29: =VLOOKUP($B29,'STOCK (1)'!$C:$O,7,0) -> #N/A | F29: =VLOOKUP($B29,'STOCK (2)'!$C:$O,7,0) -> #N/A | G29: =VLOOKUP($B29,'STOCK (3)'!$C:$O,7,0) -> #N/A | H29: =VLOOKUP($B29,'STOCK (4)'!$C:$O,7,0) -> #N/A | I29: =VLOOKUP($B29,'STOCK (5)'!$C:$O,7,0) -> #N/A
B30: =NIFTY50!A224 -> 43396 | C30: =VLOOKUP(B30,NIFTY50!$A:$G,5,0) -> 10146.8 | E30: =VLOOKUP($B30,'STOCK (1)'!$C:$O,7,0) -> #N/A | F30: =VLOOKUP($B30,'STOCK (2)'!$C:$O,7,0) -> #N/A | G30: =VLOOKUP($B30,'STOCK (3)'!$C:$O,7,0) -> #N/A | H30: =VLOOKUP($B30,'STOCK (4)'!$C:$O,7,0) -> #N/A | I30: =VLOOKUP($B30,'STOCK (5)'!$C:$O,7,0) -> #N/A
B31: =NIFTY50!A223 -> 43395 | C31: =VLOOKUP(B31,NIFTY50!$A:$G,5,0) -> 10245.25 | E31: =VLOOKUP($B31,'STOCK (1)'!$C:$O,7,0) -> #N/A | F31: =VLOOKUP($B31,'STOCK (2)'!$C:$O,7,0) -> #N/A | G31: =VLOOKUP($B31,'STOCK (3)'!$C:$O,7,0) -> #N/A | H31: =VLOOKUP($B31,'STOCK (4)'!$C:$O,7,0) -> #N/A | I31: =VLOOKUP($B31,'STOCK (5)'!$C:$O,7,0) -> #N/A
B32: =NIFTY50!A222 -> 43392 | C32: =VLOOKUP(B32,NIFTY50!$A:$G,5,0) -> 10303.55 | E32: =VLOOKUP($B32,'STOCK (1)'!$C:$O,7,0) -> #N/A | F32: =VLOOKUP($B32,'STOCK (2)'!$C:$O,7,0) -> #N/A | G32: =VLOOKUP($B32,'STOCK (3)'!$C:$O,7,0) -> #N/A | H32: =VLOOKUP($B32,'STOCK (4)'!$C:$O,7,0) -> #N/A | I32: =VLOOKUP($B32,'STOCK (5)'!$C:$O,7,0) -> #N/A
B33: =NIFTY50!A221 -> 43390 | C33: =VLOOKUP(B33,NIFTY50!$A:$G,5,0) -> 10453.05 | E33: =VLOOKUP($B33,'STOCK (1)'!$C:$O,7,0) -> #N/A | F33: =VLOOKUP($B33,'STOCK (2)'!$C:$O,7,0) -> #N/A | G33: =VLOOKUP($B33,'STOCK (3)'!$C:$O,7,0) -> #N/A | H33: =VLOOKUP($B33,'STOCK (4)'!$C:$O,7,0) -> #N/A | I33: =VLOOKUP($B33,'STOCK (5)'!$C:$O,7,0) -> #N/A
B34: =NIFTY50!A220 -> 43389 | C34: =VLOOKUP(B34,NIFTY50!$A:$G,5,0) -> 10584.75 | E34: =VLOOKUP($B34,'STOCK (1)'!$C:$O,7,0) -> #N/A | F34: =VLOOKUP($B34,'STOCK (2)'!$C:$O,7,0) -> #N/A | G34: =VLOOKUP($B34,'STOCK (3)'!$C:$O,7,0) -> #N/A | H34: =VLOOKUP($B34,'STOCK (4)'!$C:$O,7,0) -> #N/A | I34: =VLOOKUP($B34,'STOCK (5)'!$C:$O,7,0) -> #N/A
B35: =NIFTY50!A219 -> 43388 | C35: =VLOOKUP(B35,NIFTY50!$A:$G,5,0) -> 10512.5 | E35: =VLOOKUP($B35,'STOCK (1)'!$C:$O,7,0) -> #N/A | F35: =VLOOKUP($B35,'STOCK (2)'!$C:$O,7,0) -> #N/A | G35: =VLOOKUP($B35,'STOCK (3)'!$C:$O,7,0) -> #N/A | H35: =VLOOKUP($B35,'STOCK (4)'!$C:$O,7,0) -> #N/A | I35: =VLOOKUP($B35,'STOCK (5)'!$C:$O,7,0) -> #N/A
B36: =NIFTY50!A218 -> 43385 | C36: =VLOOKUP(B36,NIFTY50!$A:$G,5,0) -> 10472.5 | E36: =VLOOKUP($B36,'STOCK (1)'!$C:$O,7,0) -> #N/A | F36: =VLOOKUP($B36,'STOCK (2)'!$C:$O,7,0) -> #N/A | G36: =VLOOKUP($B36,'STOCK (3)'!$C:$O,7,0) -> #N/A | H36: =VLOOKUP($B36,'STOCK (4)'!$C:$O,7,0) -> #N/A | I36: =VLOOKUP($B36,'STOCK (5)'!$C:$O,7,0) -> #N/A
B37: =NIFTY50!A217 -> 43384 | C37: =VLOOKUP(B37,NIFTY50!$A:$G,5,0) -> 10234.65 | E37: =VLOOKUP($B37,'STOCK (1)'!$C:$O,7,0) -> 891.7 | F37: =VLOOKUP($B37,'STOCK (2)'!$C:$O,7,0) -> 760.8 | G37: =VLOOKUP($B37,'STOCK (3)'!$C:$O,7,0) -> 152.95 | H37: =VLOOKUP($B37,'STOCK (4)'!$C:$O,7,0) -> 727.95 | I37: =VLOOKUP($B37,'STOCK (5)'!$C:$O,7,0) -> 262.15
B38: =NIFTY50!A216 -> 43383 | C38: =VLOOKUP(B38,NIFTY50!$A:$G,5,0) -> 10460.1 | E38: =VLOOKUP($B38,'STOCK (1)'!$C:$O,7,0) -> 978.25 | F38: =VLOOKUP($B38,'STOCK (2)'!$C:$O,7,0) -> 744.45 | G38: =VLOOKUP($B38,'STOCK (3)'!$C:$O,7,0) -> 148.6 | H38: =VLOOKUP($B38,'STOCK (4)'!$C:$O,7,0) -> 718.6 | I38: =VLOOKUP($B38,'STOCK (5)'!$C:$O,7,0) -> 278.65
B39: =NIFTY50!A215 -> 43382 | C39: =VLOOKUP(B39,NIFTY50!$A:$G,5,0) -> 10301.05 | E39: =VLOOKUP($B39,'STOCK (1)'!$C:$O,7,0) -> 946.3 | F39: =VLOOKUP($B39,'STOCK (2)'!$C:$O,7,0) -> 724.45 | G39: =VLOOKUP($B39,'STOCK (3)'!$C:$O,7,0) -> 146.65 | H39: =VLOOKUP($B39,'STOCK (4)'!$C:$O,7,0) -> 669.1 | I39: =VLOOKUP($B39,'STOCK (5)'!$C:$O,7,0) -> 262.95
B40: =NIFTY50!A214 -> 43381 | C40: =VLOOKUP(B40,NIFTY50!$A:$G,5,0) -> 10348.05 | E40: =VLOOKUP($B40,'STOCK (1)'!$C:$O,7,0) -> 940.15 | F40: =VLOOKUP($B40,'STOCK (2)'!$C:$O,7,0) -> 781.85 | G40: =VLOOKUP($B40,'STOCK (3)'!$C:$O,7,0) -> 149.8 | H40: =VLOOKUP($B40,'STOCK (4)'!$C:$O,7,0) -> 698.15 | I40: =VLOOKUP($B40,'STOCK (5)'!$C:$O,7,0) -> 265.75
...

Sheet NIFTY50
A1: Date | B1: Open | C1: High | D1: Low | E1: Close | F1: Shares Traded | G1: Turnover (Rs. Cr) | I1: https://www.nseindia.com/products/content/equities/indices/historical_index_data.htm
A2: 43067 | B2: 10387.9 | C2: 10409.55 | D2: 10355.2 | E2: 10370.25 | F2: 202050866 | G2: 9979.25
A3: 43068 | B3: 10376.65 | C3: 10392.95 | D3: 10345.9 | E3: 10361.3 | F3: 157192930 | G3: 8852.8
A4: 43069 | B4: 10332.7 | C4: 10332.7 | D4: 10211.25 | E4: 10226.55 | F4: 353105240 | G4: 19005.56
A5: 43070 | B5: 10263.7 | C5: 10272.7 | D5: 10108.55 | E5: 10121.8 | F5: 147765528 | G5: 8518.58
A6: 43073 | B6: 10175.05 | C6: 10179.2 | D6: 10095.7 | E6: 10127.75 | F6: 153240126 | G6: 8458.66
A7: 43074 | B7: 10118.25 | C7: 10147.95 | D7: 10069.1 | E7: 10118.25 | F7: 160253042 | G7: 8749.09
A8: 43075 | B8: 10088.8 | C8: 10104.2 | D8: 10033.35 | E8: 10044.1 | F8: 171208366 | G8: 9598.82
A9: 43076 | B9: 10063.45 | C9: 10182.65 | D9: 10061.9 | E9: 10166.7 | F9: 171339022 | G9: 9910.28
A10: 43077 | B10: 10198.45 | C10: 10270.85 | D10: 10195.25 | E10: 10265.65 | F10: 206234019 | G10: 11468.15
A11: 43080 | B11: 10310.5 | C11: 10329.2 | D11: 10282.05 | E11: 10322.25 | F11: 152034656 | G11: 8453.76
A12: 43081 | B12: 10324.9 | C12: 10326.1 | D12: 10230.2 | E12: 10240.15 | F12: 180546894 | G12: 10380.24
A13: 43082 | B13: 10236.6 | C13: 10296.55 | D13: 10169.85 | E13: 10192.95 | F13: 187191964 | G13: 10070.44
... A232: 43406 | B232: 10462.3 | C232: 10606.95 | D232: 10457.7 | E232: 10553 | F232: 434175607 | G232: 21758.8
A233: 43409 | B233: 10558.75 | C233: 10558.8 | D233: 10477 | E233: 10524 | F233: - | G233: -
A234: 43410 | B234: 10552 | C234: 10600.25 | D234: 10491.45 | E234: 10530 | F234: 309878810 | G234: 14006.19
A235: 43411 | B235: 10614.45 | C235: 10616.45 | D235: 10582.3 | E235: 10598.4 | F235: - | G235: -
A236: 43413 | B236: 10614.7 | C236: 10619.55 | D236: 10544.85 | E236: 10585.2 | F236: 305817331 | G236: 15294.83
A237: 43416 | B237: 10607.8 | C237: 10645.5 | D237: 10464.05 | E237: 10482.2 | F237: 267710127 | G237: 13445.33
A238: 43417 | B238: 10451.9 | C238: 10596.25 | D238: 10440.55 | E238: 10582.5 | F238: 262541595 | G238: 13078.98
A239: 43418 | B239: 10634.9 | C239: 10651.6 | D239: 10532.7 | E239: 10576.3 | F239: 396373781 | G239: 19374.89
A240: 43419 | B240: 10580.6 | C240: 10646.5 | D240: 10557.5 | E240: 10616.7 | F240: 306011926 | G240: 14937.67
A241: 43420 | B241: 10644 | C241: 10695.15 | D241: 10631.15 | E241: 10682.2 | F241: 353384918 | G241: 16728.88
A242: 43423 | B242: 10731.25 | C242: 10774.7 | D242: 10688.8 | E242: 10763.4 | F242: 280522364 | G242: 13540.9
A243: 43424 | B243: 10740.1 | C243: 10740.85 | D243: 10640.85 | E243: 10656.2 | F243: 304322623 | G243: 13077.24
A244: 43425 | B244: 10670.95 | C244: 10671.3 | D244: 10562.35 | E244: 10600.05 | F244: 310191008 | G244: 15382.32
A245: 43426 | B245: 10612.65 | C245: 10646.25 | D245: 10512 | E245: 10526.75 | F245: 246926671 | G245: 12254.36
A246: 43430 | B246: 10568.3 | C246: 10637.8 | D246: 10489.75 | E246: 10628.6 | F246: 332863041 | G246: 15927.25
A247: 43431 | B247: 10621.45 | C247: 10695.15 | D247: 10596.35 | E247: 10685.6 | F247: 382834178 | G247: 17296.28

Sheet STOCK (1)
A1: Symbol | B1: Series | C1: Date | D1: Prev Close | E1: Open Price | F1: High Price | G1: Low Price | H1: Last Price | I1: Close Price | J1: Average Price | K1: Total Traded Quantity | L1: Turnover | M1: No. of Trades | N1: Deliverable Qty | O1: % Dly Qt to Traded Qty | R1: https://www.nseindia.com/products/content/equities/equities/eq_security.htm
A2: IBULHSGFIN | B2: EQ | C2: 43020 | D2: 1260.4 | E2: 1256 | F2: 1276.4 | G2: 1252.4 | H2: 1272.1 | I2: 1272.45 | J2: 1262.66 | K2: 956856 | L2: 1.2081855e+09 | M2: 30918 | N2: 431745 | O2: 45.12
A3: IBULHSGFIN | B3: EQ | C3: 43021 | D3: 1272.45 | E3: 1275 | F3: 1292.6 | G3: 1267 | H3: 1283.45 | I3: 1282.7 | J3: 1280.43 | K3: 1441377 | L3: 1.8455831e+09 | M3: 71040 | N3: 761937 | O3: 52.86
A4: IBULHSGFIN | B4: EQ | C4: 43024 | D4: 1282.7 | E4: 1294 | F4: 1299.95 | G4: 1276.8 | H4: 1299.95 | I4: 1295.1 | J4: 1286.76 | K4: 1033785 | L4: 1.3302296e+09 | M4: 65079 | N4: 599619 | O4: 58
A5: IBULHSGFIN | B5: EQ | C5: 43025 | D5: 1295.1 | E5: 1296 | F5: 1340.95 | G5: 1295.3 | H5: 1324.6 | I5: 1325.7 | J5: 1320.44 | K5: 2059391 | L5: 2.7192932e+09 | M5: 85192 | N5: 937054 | O5: 45.5
A6: IBULHSGFIN | B6: EQ | C6: 43026 | D6: 1325.7 | E6: 1326.5 | F6: 1367 | G6: 1320 | H6: 1364 | I6: 1358.4 | J6: 1345.66 | K6: 1828010 | L6: 2.4598763e+09 | M6: 51493 | N6: 853028 | O6: 46.66
A7: IBULHSGFIN | B7: EQ | C7: 43027 | D7: 1358.4 | E7: 1361.95 | F7: 1372.3 | G7: 1351.35 | H7: 1364 | I7: 1360.7 | J7: 1364.19 | K7: 187318 | L7: 2.555372e+08 | M7: 4163 | N7: 55534 | O7: 29.65
A8: IBULHSGFIN | B8: EQ | C8: 43031 | D8: 1360.7 | E8: 1364.15 | F8: 1373.95 | G8: 1325.55 | H8: 1342.5 | I8: 1337.75 | J8: 1349.73 | K8: 2114411 | L8: 2.85389e+09 | M8: 66892 | N8: 1055310 | O8: 49.91
A9: IBULHSGFIN | B9: EQ | C9: 43032 | D9: 1337.75 | E9: 1362.3 | F9: 1365.5 | G9: 1335.3 | H9: 1342 | I9: 1342.55 | J9: 1348.87 | K9: 2060852 | L9: 2.7798135e+09 | M9: 68042 | N9: 828785 | O9: 40.22
A10: IBULHSGFIN | B10: EQ | C10: 43033 | D10: 1342.55 | E10: 1344.9 | F10: 1344.9 | G10: 1265.3 | H10: 1268.8 | I10: 1276.7 | J10: 1287.65 | K10: 2141225 | L10: 2.7571492e+09 | M10: 74811 | N10: 1215923 | O10: 56.79
A11: IBULHSGFIN | B11: EQ | C11: 43034 | D11: 1276.7 | E11: 1269 | F11: 1270 | G11: 1206.1 | H11: 1248 | I11: 1248.25 | J11: 1240.66 | K11: 4875011 | L11: 6.0482513e+09 | M11: 110779 | N11: 2960120 | O11: 60.72
A12: IBULHSGFIN | B12: EQ | C12: 43035 | D12: 1248.25 | E12: 1233.05 | F12: 1272.1 | G12: 1233.05 | H12: 1261.5 | I12: 1264.3 | J12: 1257.91 | K12: 894164 | L12: 1.1247771e+09 | M12: 38685 | N12: 396589 | O12: 44.35
A13: IBULHSGFIN | B13: EQ | C13: 43038 | D13: 1264.3 | E13: 1266 | F13: 1269.15 | G13: 1241.5 | H13: 1261 | I13: 1261.1 | J13: 1254.02 | K13: 1313007 | L13: 1.6465379e+09 | M13: 54484 | N13: 799212 | O13: 60.87
... A249: IBULHSGFIN | B249: EQ | C249: 43384 | D249: 978.25 | E249: 919 | F249: 935.5 | G249: 860.65 | H249: 889 | I249: 891.7 | J249: 902.03 | K249: 9345760 | L249: 8.4301125e+09 | M249: 251967 | N249: 2802604 | O249: 29.99

Sheet STOCK (2)
A1: Symbol | B1: Series | C1: Date | D1: Prev Close | E1: Open Price | F1: High Price | G1: Low Price | H1: Last Price | I1: Close Price | J1: Average Price | K1: Total Traded Quantity | L1: Turnover | M1: No. of Trades | N1: Deliverable Qty | O1: % Dly Qt to Traded Qty | R1: https://www.nseindia.com/products/content/equities/equities/eq_security.htm
A2: INDIGO | B2: EQ | C2: 43020 | D2: 1109.05 | E2: 1118.7 | F2: 1138.9 | G2: 1107.9 | H2: 1133 | I2: 1134.3 | J2: 1125.49 | K2: 206930 | L2: 2.3289802e+08 | M2: 15207 | N2: 76511 | O2: 36.97
A3: INDIGO | B3: EQ | C3: 43021 | D3: 1134.3 | E3: 1130 | F3: 1146 | G3: 1121.15 | H3: 1130 | I3: 1128.05 | J3: 1136.13 | K3: 275519 | L3: 3.1302552e+08 | M3: 20441 | N3: 116639 | O3: 42.33
A4: INDIGO | B4: EQ | C4: 43024 | D4: 1128.05 | E4: 1136.8 | F4: 1136.8 | G4: 1116 | H4: 1127.7 | I4: 1121.45 | J4: 1120.8 | K4: 275211 | L4: 3.0845552e+08 | M4: 21721 | N4: 98636 | O4: 35.84
A5: INDIGO | B5: EQ | C5: 43025 | D5: 1121.45 | E5: 1128.4 | F5: 1128.4 | G5: 1105.95 | H5: 1107.25 | I5: 1109.55 | J5: 1111.91 | K5: 351418 | L5: 3.907458e+08 | M5: 40058 | N5: 195325 | O5: 55.58
A6: INDIGO | B6: EQ | C6: 43026 | D6: 1109.55 | E6: 1105 | F6: 1162.95 | G6: 1096.95 | H6: 1148.6 | I6: 1149.15 | J6: 1136.97 | K6: 797328 | L6: 9.0653872e+08 | M6: 38061 | N6: 369170 | O6: 46.3
A7: INDIGO | B7: EQ | C7: 43027 | D7: 1149.15 | E7: 1157 | F7: 1173.75 | G7: 1140 | H7: 1151.55 | I7: 1158.85 | J7: 1164.43 | K7: 171975 | L7: 2.0025322e+08 | M7: 4529 | N7: 63873 | O7: 37.14
A8: INDIGO | B8: EQ | C8: 43031 | D8: 1158.85 | E8: 1158 | F8: 1172.65 | G8: 1148.1 | H8: 1160 | I8: 1159.6 | J8: 1159.5 | K8: 368070 | L8: 4.2677707e+08 | M8: 34619 | N8: 182549 | O8: 49.6
A9: INDIGO | B9: EQ | C9: 43032 | D9: 1159.6 | E9: 1160.7 | F9: 1177 | G9: 1151 | H9: 1171 | I9: 1167.7 | J9: 1167.14 | K9: 566127 | L9: 6.6074783e+08 | M9: 32127 | N9: 243656 | O9: 43.04
A10: INDIGO | B10: EQ | C10: 43033 | D10: 1167.7 | E10: 1165 | F10: 1179 | G10: 1153.1 | H10: 1165.25 | I10: 1173.85 | J10: 1169.61 | K10: 567426 | L10: 6.6366575e+08 | M10: 21409 | N10: 370012 | O10: 65.21
A11: INDIGO | B11: EQ | C11: 43034 | D11: 1173.85 | E11: 1166.25 | F11: 1183 | G11: 1154.65 | H11: 1170 | I11: 1168.7 | J11: 1170.37 | K11: 389733 | L11: 4.5613189e+08 | M11: 20839 | N11: 179203 | O11: 45.98
A12: INDIGO | B12: EQ | C12: 43035 | D12: 1168.7 | E12: 1169 | F12: 1214.45 | G12: 1169 | H12: 1199.95 | I12: 1202.45 | J12: 1199.06 | K12: 709772 | L12: 8.5106054e+08 | M12: 22312 | N12: 355167 | O12: 50.04
A13: INDIGO | B13: EQ | C13: 43038 | D13: 1202.45 | E13: 1200 | F13: 1231.85 | G13: 1198.85 | H13: 1229.7 | I13: 1225.15 | J13: 1223.01 | K13: 948373 | L13: 1.1598656e+09 | M13: 38484 | N13: 527427 | O13: 55.61
... A249: INDIGO | B249: EQ | C249: 43384 | D249: 744.45 | E249: 725 | F249: 801.65 | G249: 714.1 | H249: 760.1 | I249: 760.8 | J249: 775.97 | K249: 4441595 | L249: 3446563594 | M249: 140416 | N249: 1695312 | O249: 38.17

Sheet STOCK (3)
A1: Symbol | B1: Series | C1: Date | D1: Prev Close | E1: Open Price | F1: High Price | G1: Low Price | H1: Last Price | I1: Close Price | J1: Average Price | K1: Total Traded Quantity | L1: Turnover | M1: No. of Trades | N1: Deliverable Qty | O1: % Dly Qt to Traded Qty | R1: https://www.nseindia.com/products/content/equities/equities/eq_security.htm
A2: ONGC | B2: EQ | C2: 43020 | D2: 169.15 | E2: 169.7 | F2: 170.6 | G2: 167.75 | H2: 169.65 | I2: 169.7 | J2: 168.85 | K2: 4877955 | L2: 823627787 | M2: 33067 | N2: 3055565 | O2: 62.64
A3: ONGC | B3: EQ | C3: 43021 | D3: 169.7 | E3: 169.15 | F3: 170.35 | G3: 168.3 | H3: 169.65 | I3: 169.65 | J3: 169.41 | K3: 5190805 | L3: 8.7936208e+08 | M3: 30727 | N3: 3374088 | O3: 65
A4: ONGC | B4: EQ | C4: 43024 | D4: 169.65 | E4: 170.45 | F4: 172.9 | G4: 170.05 | H4: 171.75 | I4: 172.05 | J4: 171.74 | K4: 5054731 | L4: 8.681097e+08 | M4: 42756 | N4: 3055836 | O4: 60.45
A5: ONGC | B5: EQ | C5: 43025 | D5: 172.05 | E5: 171.15 | F5: 172 | G5: 170 | H5: 171.5 | I5: 171.2 | J5: 170.86 | K5: 6819547 | L5: 1.1651612e+09 | M5: 71042 | N5: 5080927 | O5: 74.51
A6: ONGC | B6: EQ | C6: 43026 | D6: 171.2 | E6: 171 | F6: 174.95 | G6: 170.5 | H6: 174.75 | I6: 174.45 | J6: 173.82 | K6: 7869107 | L6: 1.3677869e+09 | M6: 58615 | N6: 4524574 | O6: 57.5
A7: ONGC | B7: EQ | C7: 43027 | D7: 174.45 | E7: 175 | F7: 175.5 | G7: 171.3 | H7: 172.15 | I7: 172.05 | J7: 172.85 | K7: 1215089 | L7: 2.100285e+08 | M7: 7813 | N7: 463093 | O7: 38.11
A8: ONGC | B8: EQ | C8: 43031 | D8: 172.05 | E8: 172.9 | F8: 173.4 | G8: 170.55 | H8: 172 | I8: 171.7 | J8: 171.79 | K8: 4126469 | L8: 7.0888048e+08 | M8: 41611 | N8: 2470666 | O8: 59.87
A9: ONGC | B9: EQ | C9: 43032 | D9: 171.7 | E9: 171.5 | F9: 177.25 | G9: 171.05 | H9: 176.35 | I9: 176 | J9: 175.94 | K9: 10817861 | L9: 1.9032539e+09 | M9: 90415 | N9: 4704292 | O9: 43.49
A10: ONGC | B10: EQ | C10: 43033 | D10: 176 | E10: 177.95 | F10: 178.3 | G10: 175.55 | H10: 176.45 | I10: 176.85 | J10: 177.06 | K10: 6103342 | L10: 1.0806287e+09 | M10: 40272 | N10: 3566091 | O10: 58.43
A11: ONGC | B11: EQ | C11: 43034 | D11: 176.85 | E11: 176.45 | F11: 180 | G11: 175.9 | H11: 176.9 | I11: 177.35 | J11: 177.77 | K11: 15326252 | L11: 2.7245247e+09 | M11: 50669 | N11: 11311140 | O11: 73.8
A12: ONGC | B12: EQ | C12: 43035 | D12: 177.35 | E12: 177.9 | F12: 184.9 | G12: 177.2 | H12: 184.05 | I12: 184 | J12: 181.99 | K12: 9866477 | L12: 1.7956273e+09 | M12: 73436 | N12: 4676571 | O12: 47.4
A13: ONGC | B13: EQ | C13: 43038 | D13: 184 | E13: 188 | F13: 191.35 | G13: 186 | H13: 186.35 | I13: 186.6 | J13: 188.72 | K13: 16606395 | L13: 3.1340363e+09 | M13: 90033 | N13: 6163375 | O13: 37.11
... A249: ONGC | B249: EQ | C249: 43384 | D249: 148.6 | E249: 146.1 | F249: 159.6 | G249: 146.1 | H249: 152.65 | I249: 152.95 | J249: 153.4 | K249: 15633772 | L249: 2.3982791e+09 | M249: 138574 | N249: 6796056 | O249: 43.47

Sheet STOCK (4)
A1: Symbol | B1: Series | C1: Date | D1: Prev Close | E1: Open Price | F1: High Price | G1: Low Price | H1: Last Price | I1: Close Price | J1: Average Price | K1: Total Traded Quantity | L1: Turnover | M1: No. of Trades | N1: Deliverable Qty | O1: % Dly Qt to Traded Qty | R1: https://www.nseindia.com/products/content/equities/equities/eq_security.htm
A2: GODREJCP | B2: EQ | C2: 43020 | D2: 979.7 | E2: 980 | F2: 985 | G2: 971.05 | H2: 976.25 | I2: 974.55 | J2: 976.45 | K2: 276972 | L2: 2.7044852e+08 | M2: 8154 | N2: 168305 | O2: 60.77
A3: GODREJCP | B3: EQ | C3: 43021 | D3: 974.55 | E3: 975.05 | F3: 978.35 | G3: 965 | H3: 973.3 | I3: 971.25 | J3: 968.75 | K3: 280924 | L3: 2.7214493e+08 | M3: 11826 | N3: 171875 | O3: 61.18
A4: GODREJCP | B4: EQ | C4: 43024 | D4: 971.25 | E4: 982 | F4: 987.95 | G4: 969.4 | H4: 978 | I4: 976.25 | J4: 977.51 | K4: 787695 | L4: 7.6998101e+08 | M4: 31300 | N4: 448828 | O4: 56.98
A5: GODREJCP | B5: EQ | C5: 43025 | D5: 976.25 | E5: 972.05 | F5: 981.75 | G5: 965.1 | H5: 968.1 | I5: 969.2 | J5: 970.56 | K5: 301590 | L5: 2.9271121e+08 | M5: 19840 | N5: 160705 | O5: 53.29
A6: GODREJCP | B6: EQ | C6: 43026 | D6: 969.2 | E6: 970.7 | F6: 973.55 | G6: 963 | H6: 964.5 | I6: 965.05 | J6: 967.64 | K6: 411683 | L6: 3.9835942e+08 | M6: 12116 | N6: 305441 | O6: 74.19
A7: GODREJCP | B7: EQ | C7: 43027 | D7: 965.05 | E7: 970 | F7: 970 | G7: 955 | H7: 958 | I7: 958.95 | J7: 962.01 | K7: 22837 | L7: 21969500 | M7: 2007 | N7: 8877 | O7: 38.87
A8: GODREJCP | B8: EQ | C8: 43031 | D8: 958.95 | E8: 964.95 | F8: 964.95 | G8: 928 | H8: 935.15 | I8: 938.2 | J8: 943.86 | K8: 383262 | L8: 3.6174399e+08 | M8: 38866 | N8: 274842 | O8: 71.71
A9: GODREJCP | B9: EQ | C9: 43032 | D9: 938.2 | E9: 942.7 | F9: 949 | G9: 930.55 | H9: 934.9 | I9: 932.65 | J9: 937.36 | K9: 255865 | L9: 2.3983808e+08 | M9: 16733 | N9: 174366 | O9: 68.15
A10: GODREJCP | B10: EQ | C10: 43033 | D10: 932.65 | E10: 932.65 | F10: 942.85 | G10: 917.45 | H10: 921.5 | I10: 921.85 | J10: 923.24 | K10: 433115 | L10: 3.9986924e+08 | M10: 16436 | N10: 241004 | O10: 55.64
A11: GODREJCP | B11: EQ | C11: 43034 | D11: 921.85 | E11: 917 | F11: 928.55 | G11: 910 | H11: 924 | I11: 923.05 | J11: 921.84 | K11: 429039 | L11: 3.9550633e+08 | M11: 19825 | N11: 226424 | O11: 52.77
A12: GODREJCP | B12: EQ | C12: 43035 | D12: 923.05 | E12: 929 | F12: 938.15 | G12: 916.05 | H12: 930 | I12: 926.9 | J12: 926.25 | K12: 327573 | L12: 3.0341472e+08 | M12: 18618 | N12: 187932 | O12: 57.37
A13: GODREJCP | B13: EQ | C13: 43038 | D13: 926.9 | E13: 931 | F13: 933 | G13: 922.3 | H13: 932 | I13: 926.3 | J13: 927.77 | K13: 352622 | L13: 3.2715141e+08 | M13: 24830 | N13: 246653 | O13: 69.95
... A249: GODREJCP | B249: EQ | C249: 43384 | D249: 718.6 | E249: 693.6 | F249: 736.2 | G249: 688.2 | H249: 728.3 | I249: 727.95 | J249: 711.6 | K249: 1085121 | L249: 7.7216701e+08 | M249: 39264 | N249: 579643 | O249: 53.42

Sheet STOCK (5)
A1: Symbol | B1: Series | C1: Date | D1: Prev Close | E1: Open Price | F1: High Price | G1: Low Price | H1: Last Price | I1: Close Price | J1: Average Price | K1: Total Traded Quantity | L1: Turnover | M1: No. of Trades | N1: Deliverable Qty | O1: % Dly Qt to Traded Qty | R1: https://www.nseindia.com/products/content/equities/equities/eq_security.htm
A2: SBIN | B2: EQ | C2: 43020 | D2: 251.75 | E2: 252 | F2: 252.95 | G2: 248.5 | H2: 250.65 | I2: 251.2 | J2: 250.53 | K2: 13404759 | L2: 3.3582874e+09 | M2: 126202 | N2: 6406726 | O2: 47.79
A3: SBIN | B3: EQ | C3: 43021 | D3: 251.2 | E3: 251.1 | F3: 255.35 | G3: 250.2 | H3: 252.1 | I3: 252.1 | J3: 253.25 | K3: 15697555 | L3: 3.9754053e+09 | M3: 115906 | N3: 7241201 | O3: 46.13
A4: SBIN | B4: EQ | C4: 43024 | D4: 252.1 | E4: 254.6 | F4: 254.7 | G4: 250.1 | H4: 252.05 | I4: 252.05 | J4: 252 | K4: 12171830 | L4: 3.0673137e+09 | M4: 105858 | N4: 5235819 | O4: 43.02
A5: SBIN | B5: EQ | C5: 43025 | D5: 252.05 | E5: 252.05 | F5: 254.7 | G5: 250.65 | H5: 251.35 | I5: 251.15 | J5: 252.36 | K5: 13505216 | L5: 3.4082041e+09 | M5: 86288 | N5: 6179816 | O5: 45.76
A6: SBIN | B6: EQ | C6: 43026 | D6: 251.15 | E6: 246 | F6: 247.8 | G6: 242.55 | H6: 244.5 | I6: 243.75 | J6: 245.12 | K6: 20677891 | L6: 5.0686216e+09 | M6: 146946 | N6: 9285060 | O6: 44.9
A7: SBIN | B7: EQ | C7: 43027 | D7: 243.75 | E7: 243.8 | F7: 245.25 | G7: 241.15 | H7: 242.2 | I7: 242.75 | J7: 243.59 | K7: 3458869 | L7: 8.4256215e+08 | M7: 39363 | N7: 1835629 | O7: 53.07
A8: SBIN | B8: EQ | C8: 43031 | D8: 242.75 | E8: 244 | F8: 247 | G8: 242.3 | H8: 246.05 | I8: 245.95 | J8: 244.98 | K8: 8901335 | L8: 2.1806346e+09 | M8: 88204 | N8: 3167059 | O8: 35.58
A9: SBIN | B9: EQ | C9: 43032 | D9: 245.95 | E9: 246 | F9: 255.3 | G9: 245.95 | H9: 254.9 | I9: 254.45 | J9: 252.11 | K9: 17197805 | L9: 4.3357905e+09 | M9: 135463 | N9: 4966648 | O9: 28.88
A10: SBIN | B10: EQ | C10: 43033 | D10: 254.45 | E10: 279.85 | F10: 328.05 | G10: 279.85 | H10: 322.95 | I10: 324.9 | J10: 310.73 | K10: 262677081 | L10: 8.1621409e+10 | M10: 1057768 | N10: 133331056 | O10: 50.76
A11: SBIN | B11: EQ | C11: 43034 | D11: 324.9 | E11: 330 | F11: 351.3 | G11: 317.5 | H11: 318.3 | I11: 320.5 | J11: 330.14 | K11: 112804243 | L11: 3.724171e+10 | M11: 542013 | N11: 38893620 | O11: 34.48
A12: SBIN | B12: EQ | C12: 43035 | D12: 320.5 | E12: 320.25 | F12: 323.6 | G12: 310.1 | H12: 310.6 | I12: 311.05 | J12: 315.48 | K12: 27580765 | L12: 8.7012245e+09 | M12: 177962 | N12: 10473830 | O12: 37.98
A13: SBIN | B13: EQ | C13: 43038 | D13: 311.05 | E13: 312 | F13: 322.35 | G13: 310.6 | H13: 313 | I13: 312 | J13: 315.25 | K13: 28530254 | L13: 8994082068 | M13: 187294 | N13: 10389630 | O13: 36.42
... A249: SBIN | B249: EQ | C249: 43384 | D249: 278.65 | E249: 268 | F249: 271.5 | G249: 260.6 | H249: 261.7 | I249: 262.15 | J249: 263.79 | K249: 46291120 | L249: 1.2211096e+10 | M249: 263698 | N249: 18904381 | O249: 40.84
